Workbook

Sheet Estadísticas
A2: Total de sitios visitados | J2: Errores por tipo de sitio | V2: Sitio | W2: Calif 1 | X2: Calif 2 | Y2: Resultado
A3: Tipo de espacio | C3: León | D3: Silao | E3: Guanajuato | F3: Irapuato | G3: Salamanca | H3: Celaya | I3: Total | J3: Error visita 1 | K3: Error visita 2 | V3: 1 | W3: =VLOOKUP(V3,'BD1'!$A$2:$AF$1139,31,0) -> 8 | X3: =VLOOKUP(V3,'BD2'!$A$2:$AF$1139,31,0) -> 8 | Y3: =IF(X3>W3,"Mejoría",IF(X3<W3,"Pérdida","Se mantiene")) -> Se mantiene
A4: PLAZA PÚBLICA | C4: =COUNTIFS('BD1'!C:C,Estadísticas!A4,'BD1'!H:H,Estadísticas!$C$3,'BD1'!K:K,"ok") -> 4 | D4: =COUNTIFS('BD1'!C:C,Estadísticas!A4,'BD1'!H:H,Estadísticas!$D$3,'BD1'!K:K,"ok") -> 8 | E4: =COUNTIFS('BD1'!C:C,Estadísticas!A4,'BD1'!H:H,Estadísticas!$E$3,'BD1'!K:K,"ok") -> 13 | F4: =COUNTIFS('BD1'!C:C,Estadísticas!A4,'BD1'!H:H,Estadísticas!$F$3,'BD1'!K:K,"ok") -> 28 | G4: =COUNTIFS('BD1'!C:C,Estadísticas!A4,'BD1'!H:H,Estadísticas!$G$3,'BD1'!K:K,"ok") -> 0 | H4: =COUNTIFS('BD1'!C:C,Estadísticas!A4,'BD1'!H:H,Estadísticas!$H$3,'BD1'!K:K,"ok") -> 11 | I4: =SUM(C4:H4) -> 64 | J4: =SUM(COUNTIFS('BD1'!C:C, Estadísticas!A4, 'BD1'!AE:AE,"7"),COUNTIFS('BD1'!C:C, Estadísticas!A4, 'BD1'!AE:AE,"6"),COUNTIFS('BD1'!C:C, Estadísticas!A4, 'BD1'!AE:AE,"5"),COUNTIFS('BD1'!C:C, Estadísticas!A4, 'BD1'!AE:AE,"4"),COUNTIFS('BD1'!C:C, Estadísticas!A4, 'BD1'!AE:AE,"3"),COUNTIFS('BD1'!C:C, Estadísticas!A4, 'BD1'!AE:AE,"2"),COUNTIFS('BD1'!C:C, Estadísticas!A4, 'BD1'!AE:AE,"1"),COUNTIFS('BD1'!C:C, Estadísticas!A4, 'BD1'!AE:AE,"0")) -> 8 | K4: =SUM(COUNTIFS('BD2'!C:C, Estadísticas!A4, 'BD2'!AE:AE,"7"),COUNTIFS('BD2'!C:C, Estadísticas!A4, 'BD2'!AE:AE,"6"),COUNTIFS('BD2'!C:C, Estadísticas!A4, 'BD2'!AE:AE,"5"),COUNTIFS('BD2'!C:C, Estadísticas!A4, 'BD2'!AE:AE,"4"),COUNTIFS('BD2'!C:C, Estadísticas!A4, 'BD2'!AE:AE,"3"),COUNTIFS('BD2'!C:C, Estadísticas!A4, 'BD2'!AE:AE,"2"),COUNTIFS('BD2'!C:C, Estadísticas!A4, 'BD2'!AE:AE,"1"),COUNTIFS('BD2'!C:C, Estadísticas!A4, 'BD2'!AE:AE,"0")) -> 38 | V4: 2 | W4: =VLOOKUP(V4,'BD1'!$A$2:$AF$1139,31,0) -> 8 | X4: =VLOOKUP(V4,'BD2'!$A$2:$AF$1139,31,0) -> 8 | Y4: =IF(X4>W4,"Mejoría",IF(X4<W4,"Pérdida","Se mantiene")) -> Se mantiene
A5: ESPACIO DEPORTIVO | C5: =COUNTIFS('BD1'!C:C,Estadísticas!A5,'BD1'!H:H,Estadísticas!$C$3,'BD1'!K:K,"ok") -> 15 | D5: =COUNTIFS('BD1'!C:C,Estadísticas!A5,'BD1'!H:H,Estadísticas!$D$3,'BD1'!K:K,"ok") -> 3 | E5: =COUNTIFS('BD1'!C:C,Estadísticas!A5,'BD1'!H:H,Estadísticas!$E$3,'BD1'!K:K,"ok") -> 7 | F5: =COUNTIFS('BD1'!C:C,Estadísticas!A5,'BD1'!H:H,Estadísticas!$F$3,'BD1'!K:K,"ok") -> 5 | G5: =COUNTIFS('BD1'!C:C,Estadísticas!A5,'BD1'!H:H,Estadísticas!$G$3,'BD1'!K:K,"ok") -> 0 | H5: =COUNTIFS('BD1'!C:C,Estadísticas!A5,'BD1'!H:H,Estadísticas!$H$3,'BD1'!K:K,"ok") -> 4 | I5: =SUM(C5:H5) -> 34 | J5: =SUM(COUNTIFS('BD1'!C:C, Estadísticas!A5, 'BD1'!AE:AE,"7"),COUNTIFS('BD1'!C:C, Estadísticas!A5, 'BD1'!AE:AE,"6"),COUNTIFS('BD1'!C:C, Estadísticas!A5, 'BD1'!AE:AE,"5"),COUNTIFS('BD1'!C:C, Estadísticas!A5, 'BD1'!AE:AE,"4"),COUNTIFS('BD1'!C:C, Estadísticas!A5, 'BD1'!AE:AE,"3"),COUNTIFS('BD1'!C:C, Estadísticas!A5, 'BD1'!AE:AE,"2"),COUNTIFS('BD1'!C:C, Estadísticas!A5, 'BD1'!AE:AE,"1"),COUNTIFS('BD1'!C:C, Estadísticas!A5, 'BD1'!AE:AE,"0")) -> 4 | K5: =SUM(COUNTIFS('BD2'!C:C, Estadísticas!A5, 'BD2'!AE:AE,"7"),COUNTIFS('BD2'!C:C, Estadísticas!A5, 'BD2'!AE:AE,"6"),COUNTIFS('BD2'!C:C, Estadísticas!A5, 'BD2'!AE:AE,"5"),COUNTIFS('BD2'!C:C, Estadísticas!A5, 'BD2'!AE:AE,"4"),COUNTIFS('BD2'!C:C, Estadísticas!A5, 'BD2'!AE:AE,"3"),COUNTIFS('BD2'!C:C, Estadísticas!A5, 'BD2'!AE:AE,"2"),COUNTIFS('BD2'!C:C, Estadísticas!A5, 'BD2'!AE:AE,"1"),COUNTIFS('BD2'!C:C, Estadísticas!A5, 'BD2'!AE:AE,"0")) -> 13 | O5: Mejoría | Q5: Se mantiene | S5: Pérdida | V5: 3 | W5: =VLOOKUP(V5,'BD1'!$A$2:$AF$1139,31,0) -> 8 | X5: =VLOOKUP(V5,'BD2'!$A$2:$AF$1139,31,0) -> 0 | Y5: =IF(X5>W5,"Mejoría",IF(X5<W5,"Pérdida","Se mantiene")) -> Pérdida
A6: PRESIDENCIA | C6: =COUNTIFS('BD1'!C:C,Estadísticas!A6,'BD1'!H:H,Estadísticas!$C$3,'BD1'!K:K,"ok") -> 1 | D6: =COUNTIFS('BD1'!C:C,Estadísticas!A6,'BD1'!H:H,Estadísticas!$D$3,'BD1'!K:K,"ok") -> 0 | E6: =COUNTIFS('BD1'!C:C,Estadísticas!A6,'BD1'!H:H,Estadísticas!$E$3,'BD1'!K:K,"ok") -> 1 | F6: =COUNTIFS('BD1'!C:C,Estadísticas!A6,'BD1'!H:H,Estadísticas!$F$3,'BD1'!K:K,"ok") -> 0 | G6: =COUNTIFS('BD1'!C:C,Estadísticas!A6,'BD1'!H:H,Estadísticas!$G$3,'BD1'!K:K,"ok") -> 0 | H6: =COUNTIFS('BD1'!C:C,Estadísticas!A6,'BD1'!H:H,Estadísticas!$H$3,'BD1'!K:K,"ok") -> 1 | I6: =SUM(C6:H6) -> 3 | J6: =SUM(COUNTIFS('BD1'!C:C, Estadísticas!A6, 'BD1'!AE:AE,"7"),COUNTIFS('BD1'!C:C, Estadísticas!A6, 'BD1'!AE:AE,"6"),COUNTIFS('BD1'!C:C, Estadísticas!A6, 'BD1'!AE:AE,"5"),COUNTIFS('BD1'!C:C, Estadísticas!A6, 'BD1'!AE:AE,"4"),COUNTIFS('BD1'!C:C, Estadísticas!A6, 'BD1'!AE:AE,"3"),COUNTIFS('BD1'!C:C, Estadísticas!A6, 'BD1'!AE:AE,"2"),COUNTIFS('BD1'!C:C, Estadísticas!A6, 'BD1'!AE:AE,"1"),COUNTIFS('BD1'!C:C, Estadísticas!A6, 'BD1'!AE:AE,"0")) -> 1 | K6: =SUM(COUNTIFS('BD2'!C:C, Estadísticas!A6, 'BD2'!AE:AE,"7"),COUNTIFS('BD2'!C:C, Estadísticas!A6, 'BD2'!AE:AE,"6"),COUNTIFS('BD2'!C:C, Estadísticas!A6, 'BD2'!AE:AE,"5"),COUNTIFS('BD2'!C:C, Estadísticas!A6, 'BD2'!AE:AE,"4"),COUNTIFS('BD2'!C:C, Estadísticas!A6, 'BD2'!AE:AE,"3"),COUNTIFS('BD2'!C:C, Estadísticas!A6, 'BD2'!AE:AE,"2"),COUNTIFS('BD2'!C:C, Estadísticas!A6, 'BD2'!AE:AE,"1"),COUNTIFS('BD2'!C:C, Estadísticas!A6, 'BD2'!AE:AE,"0")) -> 2 | O6: =COUNTIF(Y:Y,O5) -> 75 | Q6: =COUNTIF(Y:Y,Q5) -> 192 | S6: =COUNTIF(Y:Y,S5) -> 147 | V6: 4 | W6: =VLOOKUP(V6,'BD1'!$A$2:$AF$1139,31,0) -> 8 | X6: =VLOOKUP(V6,'BD2'!$A$2:$AF$1139,31,0) -> 8 | Y6: =IF(X6>W6,"Mejoría",IF(X6<W6,"Pérdida","Se mantiene")) -> Se mantiene
A7: CENTRO DE INVESTIGACIÓN | C7: =COUNTIFS('BD1'!C:C,Estadísticas!A7,'BD1'!H:H,Estadísticas!$C$3,'BD1'!K:K,"ok") -> 1 | D7: =COUNTIFS('BD1'!C:C,Estadísticas!A7,'BD1'!H:H,Estadísticas!$D$3,'BD1'!K:K,"ok") -> 0 | E7: =COUNTIFS('BD1'!C:C,Estadísticas!A7,'BD1'!H:H,Estadísticas!$E$3,'BD1'!K:K,"ok") -> 1 | F7: =COUNTIFS('BD1'!C:C,Estadísticas!A7,'BD1'!H:H,Estadísticas!$F$3,'BD1'!K:K,"ok") -> 0 | G7: =COUNTIFS('BD1'!C:C,Estadísticas!A7,'BD1'!H:H,Estadísticas!$G$3,'BD1'!K:K,"ok") -> 0 | H7: =COUNTIFS('BD1'!C:C,Estadísticas!A7,'BD1'!H:H,Estadísticas!$H$3,'BD1'!K:K,"ok") -> 0 | I7: =SUM(C7:H7) -> 2 | J7: =SUM(COUNTIFS('BD1'!C:C, Estadísticas!A7, 'BD1'!AE:AE,"7"),COUNTIFS('BD1'!C:C, Estadísticas!A7, 'BD1'!AE:AE,"6"),COUNTIFS('BD1'!C:C, Estadísticas!A7, 'BD1'!AE:AE,"5"),COUNTIFS('BD1'!C:C, Estadísticas!A7, 'BD1'!AE:AE,"4"),COUNTIFS('BD1'!C:C, Estadísticas!A7, 'BD1'!AE:AE,"3"),COUNTIFS('BD1'!C:C, Estadísticas!A7, 'BD1'!AE:AE,"2"),COUNTIFS('BD1'!C:C, Estadísticas!A7, 'BD1'!AE:AE,"1"),COUNTIFS('BD1'!C:C, Estadísticas!A7, 'BD1'!AE:AE,"0")) -> 1 | K7: =SUM(COUNTIFS('BD2'!C:C, Estadísticas!A7, 'BD2'!AE:AE,"7"),COUNTIFS('BD2'!C:C, Estadísticas!A7, 'BD2'!AE:AE,"6"),COUNTIFS('BD2'!C:C, Estadísticas!A7, 'BD2'!AE:AE,"5"),COUNTIFS('BD2'!C:C, Estadísticas!A7, 'BD2'!AE:AE,"4"),COUNTIFS('BD2'!C:C, Estadísticas!A7, 'BD2'!AE:AE,"3"),COUNTIFS('BD2'!C:C, Estadísticas!A7, 'BD2'!AE:AE,"2"),COUNTIFS('BD2'!C:C, Estadísticas!A7, 'BD2'!AE:AE,"1"),COUNTIFS('BD2'!C:C, Estadísticas!A7, 'BD2'!AE:AE,"0")) -> 0 | V7: 5 | W7: =VLOOKUP(V7,'BD1'!$A$2:$AF$1139,31,0) -> 8 | X7: =VLOOKUP(V7,'BD2'!$A$2:$AF$1139,31,0) -> 8 | Y7: =IF(X7>W7,"Mejoría",IF(X7<W7,"Pérdida","Se mantiene")) -> Se mantiene
A8: ESCUELA | C8: =COUNTIFS('BD1'!C:C,Estadísticas!A8,'BD1'!H:H,Estadísticas!$C$3,'BD1'!K:K,"ok") -> 153 | D8: =COUNTIFS('BD1'!C:C,Estadísticas!A8,'BD1'!H:H,Estadísticas!$D$3,'BD1'!K:K,"ok") -> 0 | E8: =COUNTIFS('BD1'!C:C,Estadísticas!A8,'BD1'!H:H,Estadísticas!$E$3,'BD1'!K:K,"ok") -> 10 | F8: =COUNTIFS('BD1'!C:C,Estadísticas!A8,'BD1'!H:H,Estadísticas!$F$3,'BD1'!K:K,"ok") -> 12 | G8: =COUNTIFS('BD1'!C:C,Estadísticas!A8,'BD1'!H:H,Estadísticas!$G$3,'BD1'!K:K,"ok") -> 13 | H8: =COUNTIFS('BD1'!C:C,Estadísticas!A8,'BD1'!H:H,Estadísticas!$H$3,'BD1'!K:K,"ok") -> 4 | I8: =SUM(C8:H8) -> 192 | J8: =SUM(COUNTIFS('BD1'!C:C, Estadísticas!A8, 'BD1'!AE:AE,"7"),COUNTIFS('BD1'!C:C, Estadísticas!A8, 'BD1'!AE:AE,"6"),COUNTIFS('BD1'!C:C, Estadísticas!A8, 'BD1'!AE:AE,"5"),COUNTIFS('BD1'!C:C, Estadísticas!A8, 'BD1'!AE:AE,"4"),COUNTIFS('BD1'!C:C, Estadísticas!A8, 'BD1'!AE:AE,"3"),COUNTIFS('BD1'!C:C, Estadísticas!A8, 'BD1'!AE:AE,"2"),COUNTIFS('BD1'!C:C, Estadísticas!A8, 'BD1'!AE:AE,"1"),COUNTIFS('BD1'!C:C, Estadísticas!A8, 'BD1'!AE:AE,"0")) -> 64 | K8: =SUM(COUNTIFS('BD2'!C:C, Estadísticas!A8, 'BD2'!AE:AE,"7"),COUNTIFS('BD2'!C:C, Estadísticas!A8, 'BD2'!AE:AE,"6"),COUNTIFS('BD2'!C:C, Estadísticas!A8, 'BD2'!AE:AE,"5"),COUNTIFS('BD2'!C:C, Estadísticas!A8, 'BD2'!AE:AE,"4"),COUNTIFS('BD2'!C:C, Estadísticas!A8, 'BD2'!AE:AE,"3"),COUNTIFS('BD2'!C:C, Estadísticas!A8, 'BD2'!AE:AE,"2"),COUNTIFS('BD2'!C:C, Estadísticas!A8, 'BD2'!AE:AE,"1"),COUNTIFS('BD2'!C:C, Estadísticas!A8, 'BD2'!AE:AE,"0")) -> 76 | N8: Visita 1 | V8: 6 | W8: =VLOOKUP(V8,'BD1'!$A$2:$AF$1139,31,0) -> 8 | X8: =VLOOKUP(V8,'BD2'!$A$2:$AF$1139,31,0) -> 8 | Y8: =IF(X8>W8,"Mejoría",IF(X8<W8,"Pérdida","Se mantiene")) -> Se mantiene
A9: OFICINA GUBERNAMENTAL | C9: =COUNTIFS('BD1'!C:C,Estadísticas!A9,'BD1'!H:H,Estadísticas!$C$3,'BD1'!K:K,"ok") -> 10 | D9: =COUNTIFS('BD1'!C:C,Estadísticas!A9,'BD1'!H:H,Estadísticas!$D$3,'BD1'!K:K,"ok") -> 6 | E9: =COUNTIFS('BD1'!C:C,Estadísticas!A9,'BD1'!H:H,Estadísticas!$E$3,'BD1'!K:K,"ok") -> 11 | F9: =COUNTIFS('BD1'!C:C,Estadísticas!A9,'BD1'!H:H,Estadísticas!$F$3,'BD1'!K:K,"ok") -> 4 | G9: =COUNTIFS('BD1'!C:C,Estadísticas!A9,'BD1'!H:H,Estadísticas!$G$3,'BD1'!K:K,"ok") -> 3 | H9: =COUNTIFS('BD1'!C:C,Estadísticas!A9,'BD1'!H:H,Estadísticas!$H$3,'BD1'!K:K,"ok") -> 4 | I9: =SUM(C9:H9) -> 38 | J9: =SUM(COUNTIFS('BD1'!C:C, Estadísticas!A9, 'BD1'!AE:AE,"7"),COUNTIFS('BD1'!C:C, Estadísticas!A9, 'BD1'!AE:AE,"6"),COUNTIFS('BD1'!C:C, Estadísticas!A9, 'BD1'!AE:AE,"5"),COUNTIFS('BD1'!C:C, Estadísticas!A9, 'BD1'!AE:AE,"4"),COUNTIFS('BD1'!C:C, Estadísticas!A9, 'BD1'!AE:AE,"3"),COUNTIFS('BD1'!C:C, Estadísticas!A9, 'BD1'!AE:AE,"2"),COUNTIFS('BD1'!C:C, Estadísticas!A9, 'BD1'!AE:AE,"1"),COUNTIFS('BD1'!C:C, Estadísticas!A9, 'BD1'!AE:AE,"0")) -> 17 | K9: =SUM(COUNTIFS('BD2'!C:C, Estadísticas!A9, 'BD2'!AE:AE,"7"),COUNTIFS('BD2'!C:C, Estadísticas!A9, 'BD2'!AE:AE,"6"),COUNTIFS('BD2'!C:C, Estadísticas!A9, 'BD2'!AE:AE,"5"),COUNTIFS('BD2'!C:C, Estadísticas!A9, 'BD2'!AE:AE,"4"),COUNTIFS('BD2'!C:C, Estadísticas!A9, 'BD2'!AE:AE,"3"),COUNTIFS('BD2'!C:C, Estadísticas!A9, 'BD2'!AE:AE,"2"),COUNTIFS('BD2'!C:C, Estadísticas!A9, 'BD2'!AE:AE,"1"),COUNTIFS('BD2'!C:C, Estadísticas!A9, 'BD2'!AE:AE,"0")) -> 20 | N9: Estable | T9: =COUNTIF('BD1'!AF:AF,Estadísticas!N9) -> 303 | V9: 7 | W9: =VLOOKUP(V9,'BD1'!$A$2:$AF$1139,31,0) -> 8 | X9: =VLOOKUP(V9,'BD2'!$A$2:$AF$1139,31,0) -> 0 | Y9: =IF(X9>W9,"Mejoría",IF(X9<W9,"Pérdida","Se mantiene")) -> Pérdida
A10: SECTOR SALUD | C10: =COUNTIFS('BD1'!C:C,Estadísticas!A10,'BD1'!H:H,Estadísticas!$C$3,'BD1'!K:K,"ok") -> 28 | D10: =COUNTIFS('BD1'!C:C,Estadísticas!A10,'BD1'!H:H,Estadísticas!$D$3,'BD1'!K:K,"ok") -> 0 | E10: =COUNTIFS('BD1'!C:C,Estadísticas!A10,'BD1'!H:H,Estadísticas!$E$3,'BD1'!K:K,"ok") -> 7 | F10: =COUNTIFS('BD1'!C:C,Estadísticas!A10,'BD1'!H:H,Estadísticas!$F$3,'BD1'!K:K,"ok") -> 4 | G10: =COUNTIFS('BD1'!C:C,Estadísticas!A10,'BD1'!H:H,Estadísticas!$G$3,'BD1'!K:K,"ok") -> 2 | H10: =COUNTIFS('BD1'!C:C,Estadísticas!A10,'BD1'!H:H,Estadísticas!$H$3,'BD1'!K:K,"ok") -> 0 | I10: =SUM(C10:H10) -> 41 | J10: =SUM(COUNTIFS('BD1'!C:C, Estadísticas!A10, 'BD1'!AE:AE,"7"),COUNTIFS('BD1'!C:C, Estadísticas!A10, 'BD1'!AE:AE,"6"),COUNTIFS('BD1'!C:C, Estadísticas!A10, 'BD1'!AE:AE,"5"),COUNTIFS('BD1'!C:C, Estadísticas!A10, 'BD1'!AE:AE,"4"),COUNTIFS('BD1'!C:C, Estadísticas!A10, 'BD1'!AE:AE,"3"),COUNTIFS('BD1'!C:C, Estadísticas!A10, 'BD1'!AE:AE,"2"),COUNTIFS('BD1'!C:C, Estadísticas!A10, 'BD1'!AE:AE,"1"),COUNTIFS('BD1'!C:C, Estadísticas!A10, 'BD1'!AE:AE,"0")) -> 8 | K10: =SUM(COUNTIFS('BD2'!C:C, Estadísticas!A10, 'BD2'!AE:AE,"7"),COUNTIFS('BD2'!C:C, Estadísticas!A10, 'BD2'!AE:AE,"6"),COUNTIFS('BD2'!C:C, Estadísticas!A10, 'BD2'!AE:AE,"5"),COUNTIFS('BD2'!C:C, Estadísticas!A10, 'BD2'!AE:AE,"4"),COUNTIFS('BD2'!C:C, Estadísticas!A10, 'BD2'!AE:AE,"3"),COUNTIFS('BD2'!C:C, Estadísticas!A10, 'BD2'!AE:AE,"2"),COUNTIFS('BD2'!C:C, Estadísticas!A10, 'BD2'!AE:AE,"1"),COUNTIFS('BD2'!C:C, Estadísticas!A10, 'BD2'!AE:AE,"0")) -> 12 | N10: Funcional con observaciones | T10: =COUNTIF('BD1'!AF:AF,Estadísticas!N10) -> 76 | V10: 8 | W10: =VLOOKUP(V10,'BD1'!$A$2:$AF$1139,31,0) -> 8 | X10: =VLOOKUP(V10,'BD2'!$A$2:$AF$1139,31,0) -> 8 | Y10: =IF(X10>W10,"Mejoría",IF(X10<W10,"Pérdida","Se mantiene")) -> Se mantiene
A11: FARMACIA | C11: =COUNTIFS('BD1'!C:C,Estadísticas!A11,'BD1'!H:H,Estadísticas!$C$3,'BD1'!K:K,"ok") -> 0 | D11: =COUNTIFS('BD1'!C:C,Estadísticas!A11,'BD1'!H:H,Estadísticas!$D$3,'BD1'!K:K,"ok") -> 0 | E11: =COUNTIFS('BD1'!C:C,Estadísticas!A11,'BD1'!H:H,Estadísticas!$E$3,'BD1'!K:K,"ok") -> 1 | F11: =COUNTIFS('BD1'!C:C,Estadísticas!A11,'BD1'!H:H,Estadísticas!$F$3,'BD1'!K:K,"ok") -> 0 | G11: =COUNTIFS('BD1'!C:C,Estadísticas!A11,'BD1'!H:H,Estadísticas!$G$3,'BD1'!K:K,"ok") -> 2 | H11: =COUNTIFS('BD1'!C:C,Estadísticas!A11,'BD1'!H:H,Estadísticas!$H$3,'BD1'!K:K,"ok") -> 0 | I11: =SUM(C11:H11) -> 3 | J11: =SUM(COUNTIFS('BD1'!C:C, Estadísticas!A11, 'BD1'!AE:AE,"7"),COUNTIFS('BD1'!C:C, Estadísticas!A11, 'BD1'!AE:AE,"6"),COUNTIFS('BD1'!C:C, Estadísticas!A11, 'BD1'!AE:AE,"5"),COUNTIFS('BD1'!C:C, Estadísticas!A11, 'BD1'!AE:AE,"4"),COUNTIFS('BD1'!C:C, Estadísticas!A11, 'BD1'!AE:AE,"3"),COUNTIFS('BD1'!C:C, Estadísticas!A11, 'BD1'!AE:AE,"2"),COUNTIFS('BD1'!C:C, Estadísticas!A11, 'BD1'!AE:AE,"1"),COUNTIFS('BD1'!C:C, Estadísticas!A11, 'BD1'!AE:AE,"0")) -> 2 | K11: =SUM(COUNTIFS('BD2'!C:C, Estadísticas!A11, 'BD2'!AE:AE,"7"),COUNTIFS('BD2'!C:C, Estadísticas!A11, 'BD2'!AE:AE,"6"),COUNTIFS('BD2'!C:C, Estadísticas!A11, 'BD2'!AE:AE,"5"),COUNTIFS('BD2'!C:C, Estadísticas!A11, 'BD2'!AE:AE,"4"),COUNTIFS('BD2'!C:C, Estadísticas!A11, 'BD2'!AE:AE,"3"),COUNTIFS('BD2'!C:C, Estadísticas!A11, 'BD2'!AE:AE,"2"),COUNTIFS('BD2'!C:C, Estadísticas!A11, 'BD2'!AE:AE,"1"),COUNTIFS('BD2'!C:C, Estadísticas!A11, 'BD2'!AE:AE,"0")) -> 1 | N11: Rendimiento bajo | T11: =COUNTIF('BD1'!AF:AF,Estadísticas!N11) -> 7 | V11: 9 | W11: =VLOOKUP(V11,'BD1'!$A$2:$AF$1139,31,0) -> 7 | X11: =VLOOKUP(V11,'BD2'!$A$2:$AF$1139,31,0) -> 8 | Y11: =IF(X11>W11,"Mejoría",IF(X11<W11,"Pérdida","Se mantiene")) -> Mejoría
A12: SECUNDARIA | C12: =COUNTIFS('BD1'!C:C,Estadísticas!A12,'BD1'!H:H,Estadísticas!$C$3,'BD1'!K:K,"ok") -> 0 | D12: =COUNTIFS('BD1'!C:C,Estadísticas!A12,'BD1'!H:H,Estadísticas!$D$3,'BD1'!K:K,"ok") -> 5 | E12: =COUNTIFS('BD1'!C:C,Estadísticas!A12,'BD1'!H:H,Estadísticas!$E$3,'BD1'!K:K,"ok") -> 0 | F12: =COUNTIFS('BD1'!C:C,Estadísticas!A12,'BD1'!H:H,Estadísticas!$F$3,'BD1'!K:K,"ok") -> 0 | G12: =COUNTIFS('BD1'!C:C,Estadísticas!A12,'BD1'!H:H,Estadísticas!$G$3,'BD1'!K:K,"ok") -> 0 | H12: =COUNTIFS('BD1'!C:C,Estadísticas!A12,'BD1'!H:H,Estadísticas!$H$3,'BD1'!K:K,"ok") -> 0 | I12: =SUM(C12:H12) -> 5 | J12: =SUM(COUNTIFS('BD1'!C:C, Estadísticas!A12, 'BD1'!AE:AE,"7"),COUNTIFS('BD1'!C:C, Estadísticas!A12, 'BD1'!AE:AE,"6"),COUNTIFS('BD1'!C:C, Estadísticas!A12, 'BD1'!AE:AE,"5"),COUNTIFS('BD1'!C:C, Estadísticas!A12, 'BD1'!AE:AE,"4"),COUNTIFS('BD1'!C:C, Estadísticas!A12, 'BD1'!AE:AE,"3"),COUNTIFS('BD1'!C:C, Estadísticas!A12, 'BD1'!AE:AE,"2"),COUNTIFS('BD1'!C:C, Estadísticas!A12, 'BD1'!AE:AE,"1"),COUNTIFS('BD1'!C:C, Estadísticas!A12, 'BD1'!AE:AE,"0")) -> 2 | K12: =SUM(COUNTIFS('BD2'!C:C, Estadísticas!A12, 'BD2'!AE:AE,"7"),COUNTIFS('BD2'!C:C, Estadísticas!A12, 'BD2'!AE:AE,"6"),COUNTIFS('BD2'!C:C, Estadísticas!A12, 'BD2'!AE:AE,"5"),COUNTIFS('BD2'!C:C, Estadísticas!A12, 'BD2'!AE:AE,"4"),COUNTIFS('BD2'!C:C, Estadísticas!A12, 'BD2'!AE:AE,"3"),COUNTIFS('BD2'!C:C, Estadísticas!A12, 'BD2'!AE:AE,"2"),COUNTIFS('BD2'!C:C, Estadísticas!A12, 'BD2'!AE:AE,"1"),COUNTIFS('BD2'!C:C, Estadísticas!A12, 'BD2'!AE:AE,"0")) -> 5 | N12: Parcialmente funcional | T12: =COUNTIF('BD1'!AF:AF,Estadísticas!N12) -> 10 | V12: 10 | W12: =VLOOKUP(V12,'BD1'!$A$2:$AF$1139,31,0) -> 8 | X12: =VLOOKUP(V12,'BD2'!$A$2:$AF$1139,31,0) -> 8 | Y12: =IF(X12>W12,"Mejoría",IF(X12<W12,"Pérdida","Se mantiene")) -> Se mantiene
A13: PREESCOLAR | C13: =COUNTIFS('BD1'!C:C,Estadísticas!A13,'BD1'!H:H,Estadísticas!$C$3,'BD1'!K:K,"ok") -> 0 | D13: =COUNTIFS('BD1'!C:C,Estadísticas!A13,'BD1'!H:H,Estadísticas!$D$3,'BD1'!K:K,"ok") -> 9 | E13: =COUNTIFS('BD1'!C:C,Estadísticas!A13,'BD1'!H:H,Estadísticas!$E$3,'BD1'!K:K,"ok") -> 0 | F13: =COUNTIFS('BD1'!C:C,Estadísticas!A13,'BD1'!H:H,Estadísticas!$F$3,'BD1'!K:K,"ok") -> 0 | G13: =COUNTIFS('BD1'!C:C,Estadísticas!A13,'BD1'!H:H,Estadísticas!$G$3,'BD1'!K:K,"ok") -> 0 | H13: =COUNTIFS('BD1'!C:C,Estadísticas!A13,'BD1'!H:H,Estadísticas!$H$3,'BD1'!K:K,"ok") -> 0 | I13: =SUM(C13:H13) -> 9 | J13: =SUM(COUNTIFS('BD1'!C:C, Estadísticas!A13, 'BD1'!AE:AE,"7"),COUNTIFS('BD1'!C:C, Estadísticas!A13, 'BD1'!AE:AE,"6"),COUNTIFS('BD1'!C:C, Estadísticas!A13, 'BD1'!AE:AE,"5"),COUNTIFS('BD1'!C:C, Estadísticas!A13, 'BD1'!AE:AE,"4"),COUNTIFS('BD1'!C:C, Estadísticas!A13, 'BD1'!AE:AE,"3"),COUNTIFS('BD1'!C:C, Estadísticas!A13, 'BD1'!AE:AE,"2"),COUNTIFS('BD1'!C:C, Estadísticas!A13, 'BD1'!AE:AE,"1"),COUNTIFS('BD1'!C:C, Estadísticas!A13, 'BD1'!AE:AE,"0")) -> 3 | K13: =SUM(COUNTIFS('BD2'!C:C, Estadísticas!A13, 'BD2'!AE:AE,"7"),COUNTIFS('BD2'!C:C, Estadísticas!A13, 'BD2'!AE:AE,"6"),COUNTIFS('BD2'!C:C, Estadísticas!A13, 'BD2'!AE:AE,"5"),COUNTIFS('BD2'!C:C, Estadísticas!A13, 'BD2'!AE:AE,"4"),COUNTIFS('BD2'!C:C, Estadísticas!A13, 'BD2'!AE:AE,"3"),COUNTIFS('BD2'!C:C, Estadísticas!A13, 'BD2'!AE:AE,"2"),COUNTIFS('BD2'!C:C, Estadísticas!A13, 'BD2'!AE:AE,"1"),COUNTIFS('BD2'!C:C, Estadísticas!A13, 'BD2'!AE:AE,"0")) -> 9 | N13: Inoperativo | T13: =COUNTIF('BD1'!AF:AF,Estadísticas!N13) -> 2 | V13: 11 | W13: =VLOOKUP(V13,'BD1'!$A$2:$AF$1139,31,0) -> 8 | X13: =VLOOKUP(V13,'BD2'!$A$2:$AF$1139,31,0) -> 8 | Y13: =IF(X13>W13,"Mejoría",IF(X13<W13,"Pérdida","Se mantiene")) -> Se mantiene
A14: PRIMARIA | C14: =COUNTIFS('BD1'!C:C,Estadísticas!A14,'BD1'!H:H,Estadísticas!$C$3,'BD1'!K:K,"ok") -> 0 | D14: =COUNTIFS('BD1'!C:C,Estadísticas!A14,'BD1'!H:H,Estadísticas!$D$3,'BD1'!K:K,"ok") -> 14 | E14: =COUNTIFS('BD1'!C:C,Estadísticas!A14,'BD1'!H:H,Estadísticas!$E$3,'BD1'!K:K,"ok") -> 0 | F14: =COUNTIFS('BD1'!C:C,Estadísticas!A14,'BD1'!H:H,Estadísticas!$F$3,'BD1'!K:K,"ok") -> 0 | G14: =COUNTIFS('BD1'!C:C,Estadísticas!A14,'BD1'!H:H,Estadísticas!$G$3,'BD1'!K:K,"ok") -> 0 | H14: =COUNTIFS('BD1'!C:C,Estadísticas!A14,'BD1'!H:H,Estadísticas!$H$3,'BD1'!K:K,"ok") -> 0 | I14: =SUM(C14:H14) -> 14 | J14: =SUM(COUNTIFS('BD1'!C:C, Estadísticas!A14, 'BD1'!AE:AE,"7"),COUNTIFS('BD1'!C:C, Estadísticas!A14, 'BD1'!AE:AE,"6"),COUNTIFS('BD1'!C:C, Estadísticas!A14, 'BD1'!AE:AE,"5"),COUNTIFS('BD1'!C:C, Estadísticas!A14, 'BD1'!AE:AE,"4"),COUNTIFS('BD1'!C:C, Estadísticas!A14, 'BD1'!AE:AE,"3"),COUNTIFS('BD1'!C:C, Estadísticas!A14, 'BD1'!AE:AE,"2"),COUNTIFS('BD1'!C:C, Estadísticas!A14, 'BD1'!AE:AE,"1"),COUNTIFS('BD1'!C:C, Estadísticas!A14, 'BD1'!AE:AE,"0")) -> 4 | K14: =SUM(COUNTIFS('BD2'!C:C, Estadísticas!A14, 'BD2'!AE:AE,"7"),COUNTIFS('BD2'!C:C, Estadísticas!A14, 'BD2'!AE:AE,"6"),COUNTIFS('BD2'!C:C, Estadísticas!A14, 'BD2'!AE:AE,"5"),COUNTIFS('BD2'!C:C, Estadísticas!A14, 'BD2'!AE:AE,"4"),COUNTIFS('BD2'!C:C, Estadísticas!A14, 'BD2'!AE:AE,"3"),COUNTIFS('BD2'!C:C, Estadísticas!A14, 'BD2'!AE:AE,"2"),COUNTIFS('BD2'!C:C, Estadísticas!A14, 'BD2'!AE:AE,"1"),COUNTIFS('BD2'!C:C, Estadísticas!A14, 'BD2'!AE:AE,"0")) -> 14 | N14: Crítico | T14: =COUNTIF('BD1'!AF:AF,Estadísticas!N14) -> 20 | V14: 12 | W14: =VLOOKUP(V14,'BD1'!$A$2:$AF$1139,31,0) -> 8 | X14: =VLOOKUP(V14,'BD2'!$A$2:$AF$1139,31,0) -> 8 | Y14: =IF(X14>W14,"Mejoría",IF(X14<W14,"Pérdida","Se mantiene")) -> Se mantiene
A15: ESPACIO CULTURAL | C15: =COUNTIFS('BD1'!C:C,Estadísticas!A15,'BD1'!H:H,Estadísticas!$C$3,'BD1'!K:K,"ok") -> 0 | D15: =COUNTIFS('BD1'!C:C,Estadísticas!A15,'BD1'!H:H,Estadísticas!$D$3,'BD1'!K:K,"ok") -> 2 | E15: =COUNTIFS('BD1'!C:C,Estadísticas!A15,'BD1'!H:H,Estadísticas!$E$3,'BD1'!K:K,"ok") -> 0 | F15: =COUNTIFS('BD1'!C:C,Estadísticas!A15,'BD1'!H:H,Estadísticas!$F$3,'BD1'!K:K,"ok") -> 0 | G15: =COUNTIFS('BD1'!C:C,Estadísticas!A15,'BD1'!H:H,Estadísticas!$G$3,'BD1'!K:K,"ok") -> 0 | H15: =COUNTIFS('BD1'!C:C,Estadísticas!A15,'BD1'!H:H,Estadísticas!$H$3,'BD1'!K:K,"ok") -> 0 | I15: =SUM(C15:H15) -> 2 | J15: =SUM(COUNTIFS('BD1'!C:C, Estadísticas!A15, 'BD1'!AE:AE,"7"),COUNTIFS('BD1'!C:C, Estadísticas!A15, 'BD1'!AE:AE,"6"),COUNTIFS('BD1'!C:C, Estadísticas!A15, 'BD1'!AE:AE,"5"),COUNTIFS('BD1'!C:C, Estadísticas!A15, 'BD1'!AE:AE,"4"),COUNTIFS('BD1'!C:C, Estadísticas!A15, 'BD1'!AE:AE,"3"),COUNTIFS('BD1'!C:C, Estadísticas!A15, 'BD1'!AE:AE,"2"),COUNTIFS('BD1'!C:C, Estadísticas!A15, 'BD1'!AE:AE,"1"),COUNTIFS('BD1'!C:C, Estadísticas!A15, 'BD1'!AE:AE,"0")) -> 1 | K15: =SUM(COUNTIFS('BD2'!C:C, Estadísticas!A15, 'BD2'!AE:AE,"7"),COUNTIFS('BD2'!C:C, Estadísticas!A15, 'BD2'!AE:AE,"6"),COUNTIFS('BD2'!C:C, Estadísticas!A15, 'BD2'!AE:AE,"5"),COUNTIFS('BD2'!C:C, Estadísticas!A15, 'BD2'!AE:AE,"4"),COUNTIFS('BD2'!C:C, Estadísticas!A15, 'BD2'!AE:AE,"3"),COUNTIFS('BD2'!C:C, Estadísticas!A15, 'BD2'!AE:AE,"2"),COUNTIFS('BD2'!C:C, Estadísticas!A15, 'BD2'!AE:AE,"1"),COUNTIFS('BD2'!C:C, Estadísticas!A15, 'BD2'!AE:AE,"0")) -> 2 | V15: 13a | W15: =VLOOKUP(V15,'BD1'!$A$2:$AF$1139,31,0) -> 8 | X15: =VLOOKUP(V15,'BD2'!$A$2:$AF$1139,31,0) -> 8 | Y15: =IF(X15>W15,"Mejoría",IF(X15<W15,"Pérdida","Se mantiene")) -> Se mantiene
A16: CENTRO DE CAPACITACIÓN | C16: =COUNTIFS('BD1'!C:C,Estadísticas!A16,'BD1'!H:H,Estadísticas!$C$3,'BD1'!K:K,"ok") -> 0 | D16: =COUNTIFS('BD1'!C:C,Estadísticas!A16,'BD1'!H:H,Estadísticas!$D$3,'BD1'!K:K,"ok") -> 0 | E16: =COUNTIFS('BD1'!C:C,Estadísticas!A16,'BD1'!H:H,Estadísticas!$E$3,'BD1'!K:K,"ok") -> 0 | F16: =COUNTIFS('BD1'!C:C,Estadísticas!A16,'BD1'!H:H,Estadísticas!$F$3,'BD1'!K:K,"ok") -> 0 | G16: =COUNTIFS('BD1'!C:C,Estadísticas!A16,'BD1'!H:H,Estadísticas!$G$3,'BD1'!K:K,"ok") -> 0 | H16: =COUNTIFS('BD1'!C:C,Estadísticas!A16,'BD1'!H:H,Estadísticas!$H$3,'BD1'!K:K,"ok") -> 0 | I16: =SUM(C16:H16) -> 0 | J16: =SUM(COUNTIFS('BD1'!C:C, Estadísticas!A16, 'BD1'!AE:AE,"7"),COUNTIFS('BD1'!C:C, Estadísticas!A16, 'BD1'!AE:AE,"6"),COUNTIFS('BD1'!C:C, Estadísticas!A16, 'BD1'!AE:AE,"5"),COUNTIFS('BD1'!C:C, Estadísticas!A16, 'BD1'!AE:AE,"4"),COUNTIFS('BD1'!C:C, Estadísticas!A16, 'BD1'!AE:AE,"3"),COUNTIFS('BD1'!C:C, Estadísticas!A16, 'BD1'!AE:AE,"2"),COUNTIFS('BD1'!C:C, Estadísticas!A16, 'BD1'!AE:AE,"1"),COUNTIFS('BD1'!C:C, Estadísticas!A16, 'BD1'!AE:AE,"0")) -> 0 | K16: =SUM(COUNTIFS('BD2'!C:C, Estadísticas!A16, 'BD2'!AE:AE,"7"),COUNTIFS('BD2'!C:C, Estadísticas!A16, 'BD2'!AE:AE,"6"),COUNTIFS('BD2'!C:C, Estadísticas!A16, 'BD2'!AE:AE,"5"),COUNTIFS('BD2'!C:C, Estadísticas!A16, 'BD2'!AE:AE,"4"),COUNTIFS('BD2'!C:C, Estadísticas!A16, 'BD2'!AE:AE,"3"),COUNTIFS('BD2'!C:C, Estadísticas!A16, 'BD2'!AE:AE,"2"),COUNTIFS('BD2'!C:C, Estadísticas!A16, 'BD2'!AE:AE,"1"),COUNTIFS('BD2'!C:C, Estadísticas!A16, 'BD2'!AE:AE,"0")) -> 0 | N16: Visita 2 | V16: 13b | W16: =VLOOKUP(V16,'BD1'!$A$2:$AF$1139,31,0) -> 7 | X16: =VLOOKUP(V16,'BD2'!$A$2:$AF$1139,31,0) -> 8 | Y16: =IF(X16>W16,"Mejoría",IF(X16<W16,"Pérdida","Se mantiene")) -> Mejoría
A17: SUPERIOR | C17: =COUNTIFS('BD1'!C:C,Estadísticas!A17,'BD1'!H:H,Estadísticas!$C$3,'BD1'!K:K,"ok") -> 0 | D17: =COUNTIFS('BD1'!C:C,Estadísticas!A17,'BD1'!H:H,Estadísticas!$D$3,'BD1'!K:K,"ok") -> 0 | E17: =COUNTIFS('BD1'!C:C,Estadísticas!A17,'BD1'!H:H,Estadísticas!$E$3,'BD1'!K:K,"ok") -> 0 | F17: =COUNTIFS('BD1'!C:C,Estadísticas!A17,'BD1'!H:H,Estadísticas!$F$3,'BD1'!K:K,"ok") -> 0 | G17: =COUNTIFS('BD1'!C:C,Estadísticas!A17,'BD1'!H:H,Estadísticas!$G$3,'BD1'!K:K,"ok") -> 0 | H17: =COUNTIFS('BD1'!C:C,Estadísticas!A17,'BD1'!H:H,Estadísticas!$H$3,'BD1'!K:K,"ok") -> 0 | I17: =SUM(C17:H17) -> 0 | J17: =SUM(COUNTIFS('BD1'!C:C, Estadísticas!A17, 'BD1'!AE:AE,"7"),COUNTIFS('BD1'!C:C, Estadísticas!A17, 'BD1'!AE:AE,"6"),COUNTIFS('BD1'!C:C, Estadísticas!A17, 'BD1'!AE:AE,"5"),COUNTIFS('BD1'!C:C, Estadísticas!A17, 'BD1'!AE:AE,"4"),COUNTIFS('BD1'!C:C, Estadísticas!A17, 'BD1'!AE:AE,"3"),COUNTIFS('BD1'!C:C, Estadísticas!A17, 'BD1'!AE:AE,"2"),COUNTIFS('BD1'!C:C, Estadísticas!A17, 'BD1'!AE:AE,"1"),COUNTIFS('BD1'!C:C, Estadísticas!A17, 'BD1'!AE:AE,"0")) -> 0 | K17: =SUM(COUNTIFS('BD2'!C:C, Estadísticas!A17, 'BD2'!AE:AE,"7"),COUNTIFS('BD2'!C:C, Estadísticas!A17, 'BD2'!AE:AE,"6"),COUNTIFS('BD2'!C:C, Estadísticas!A17, 'BD2'!AE:AE,"5"),COUNTIFS('BD2'!C:C, Estadísticas!A17, 'BD2'!AE:AE,"4"),COUNTIFS('BD2'!C:C, Estadísticas!A17, 'BD2'!AE:AE,"3"),COUNTIFS('BD2'!C:C, Estadísticas!A17, 'BD2'!AE:AE,"2"),COUNTIFS('BD2'!C:C, Estadísticas!A17, 'BD2'!AE:AE,"1"),COUNTIFS('BD2'!C:C, Estadísticas!A17, 'BD2'!AE:AE,"0")) -> 0 | N17: Estable | T17: =COUNTIF('BD2'!AF:AF,Estadísticas!N17) -> 226 | V17: 14 | W17: =VLOOKUP(V17,'BD1'!$A$2:$AF$1139,31,0) -> 8 | X17: =VLOOKUP(V17,'BD2'!$A$2:$AF$1139,31,0) -> 8 | Y17: =IF(X17>W17,"Mejoría",IF(X17<W17,"Pérdida","Se mantiene")) -> Se mantiene
A18: MEDIA SUPERIOR | C18: =COUNTIFS('BD1'!C:C,Estadísticas!A18,'BD1'!H:H,Estadísticas!$C$3,'BD1'!K:K,"ok") -> 0 | D18: =COUNTIFS('BD1'!C:C,Estadísticas!A18,'BD1'!H:H,Estadísticas!$D$3,'BD1'!K:K,"ok") -> 0 | E18: =COUNTIFS('BD1'!C:C,Estadísticas!A18,'BD1'!H:H,Estadísticas!$E$3,'BD1'!K:K,"ok") -> 0 | F18: =COUNTIFS('BD1'!C:C,Estadísticas!A18,'BD1'!H:H,Estadísticas!$F$3,'BD1'!K:K,"ok") -> 0 | G18: =COUNTIFS('BD1'!C:C,Estadísticas!A18,'BD1'!H:H,Estadísticas!$G$3,'BD1'!K:K,"ok") -> 0 | H18: =COUNTIFS('BD1'!C:C,Estadísticas!A18,'BD1'!H:H,Estadísticas!$H$3,'BD1'!K:K,"ok") -> 0 | I18: =SUM(C18:H18) -> 0 | J18: =SUM(COUNTIFS('BD1'!C:C, Estadísticas!A18, 'BD1'!AE:AE,"7"),COUNTIFS('BD1'!C:C, Estadísticas!A18, 'BD1'!AE:AE,"6"),COUNTIFS('BD1'!C:C, Estadísticas!A18, 'BD1'!AE:AE,"5"),COUNTIFS('BD1'!C:C, Estadísticas!A18, 'BD1'!AE:AE,"4"),COUNTIFS('BD1'!C:C, Estadísticas!A18, 'BD1'!AE:AE,"3"),COUNTIFS('BD1'!C:C, Estadísticas!A18, 'BD1'!AE:AE,"2"),COUNTIFS('BD1'!C:C, Estadísticas!A18, 'BD1'!AE:AE,"1"),COUNTIFS('BD1'!C:C, Estadísticas!A18, 'BD1'!AE:AE,"0")) -> 0 | K18: =SUM(COUNTIFS('BD2'!C:C, Estadísticas!A18, 'BD2'!AE:AE,"7"),COUNTIFS('BD2'!C:C, Estadísticas!A18, 'BD2'!AE:AE,"6"),COUNTIFS('BD2'!C:C, Estadísticas!A18, 'BD2'!AE:AE,"5"),COUNTIFS('BD2'!C:C, Estadísticas!A18, 'BD2'!AE:AE,"4"),COUNTIFS('BD2'!C:C, Estadísticas!A18, 'BD2'!AE:AE,"3"),COUNTIFS('BD2'!C:C, Estadísticas!A18, 'BD2'!AE:AE,"2"),COUNTIFS('BD2'!C:C, Estadísticas!A18, 'BD2'!AE:AE,"1"),COUNTIFS('BD2'!C:C, Estadísticas!A18, 'BD2'!AE:AE,"0")) -> 0 | N18: Funcional con observaciones | T18: =COUNTIF('BD2'!AF:AF,Estadísticas!N18) -> 135 | V18: 15 | W18: =VLOOKUP(V18,'BD1'!$A$2:$AF$1139,31,0) -> 8 | X18: =VLOOKUP(V18,'BD2'!$A$2:$AF$1139,31,0) -> 8 | Y18: =IF(X18>W18,"Mejoría",IF(X18<W18,"Pérdida","Se mantiene")) -> Se mantiene
A19: ESTACIONAMIENTO | C19: =COUNTIFS('BD1'!C:C,Estadísticas!A19,'BD1'!H:H,Estadísticas!$C$3,'BD1'!K:K,"ok") -> 0 | D19: =COUNTIFS('BD1'!C:C,Estadísticas!A19,'BD1'!H:H,Estadísticas!$D$3,'BD1'!K:K,"ok") -> 0 | E19: =COUNTIFS('BD1'!C:C,Estadísticas!A19,'BD1'!H:H,Estadísticas!$E$3,'BD1'!K:K,"ok") -> 0 | F19: =COUNTIFS('BD1'!C:C,Estadísticas!A19,'BD1'!H:H,Estadísticas!$F$3,'BD1'!K:K,"ok") -> 0 | G19: =COUNTIFS('BD1'!C:C,Estadísticas!A19,'BD1'!H:H,Estadísticas!$G$3,'BD1'!K:K,"ok") -> 0 | H19: =COUNTIFS('BD1'!C:C,Estadísticas!A19,'BD1'!H:H,Estadísticas!$H$3,'BD1'!K:K,"ok") -> 1 | I19: =SUM(C19:H19) -> 1 | J19: =SUM(COUNTIFS('BD1'!C:C, Estadísticas!A19, 'BD1'!AE:AE,"7"),COUNTIFS('BD1'!C:C, Estadísticas!A19, 'BD1'!AE:AE,"6"),COUNTIFS('BD1'!C:C, Estadísticas!A19, 'BD1'!AE:AE,"5"),COUNTIFS('BD1'!C:C, Estadísticas!A19, 'BD1'!AE:AE,"4"),COUNTIFS('BD1'!C:C, Estadísticas!A19, 'BD1'!AE:AE,"3"),COUNTIFS('BD1'!C:C, Estadísticas!A19, 'BD1'!AE:AE,"2"),COUNTIFS('BD1'!C:C, Estadísticas!A19, 'BD1'!AE:AE,"1"),COUNTIFS('BD1'!C:C, Estadísticas!A19, 'BD1'!AE:AE,"0")) -> 0 | K19: =SUM(COUNTIFS('BD2'!C:C, Estadísticas!A19, 'BD2'!AE:AE,"7"),COUNTIFS('BD2'!C:C, Estadísticas!A19, 'BD2'!AE:AE,"6"),COUNTIFS('BD2'!C:C, Estadísticas!A19, 'BD2'!AE:AE,"5"),COUNTIFS('BD2'!C:C, Estadísticas!A19, 'BD2'!AE:AE,"4"),COUNTIFS('BD2'!C:C, Estadísticas!A19, 'BD2'!AE:AE,"3"),COUNTIFS('BD2'!C:C, Estadísticas!A19, 'BD2'!AE:AE,"2"),COUNTIFS('BD2'!C:C, Estadísticas!A19, 'BD2'!AE:AE,"1"),COUNTIFS('BD2'!C:C, Estadísticas!A19, 'BD2'!AE:AE,"0")) -> 0 | N19: Rendimiento bajo | T19: =COUNTIF('BD2'!AF:AF,Estadísticas!N19) -> 4 | V19: 16 | W19: =VLOOKUP(V19,'BD1'!$A$2:$AF$1139,31,0) -> 8 | X19: =VLOOKUP(V19,'BD2'!$A$2:$AF$1139,31,0) -> 8 | Y19: =IF(X19>W19,"Mejoría",IF(X19<W19,"Pérdida","Se mantiene")) -> Se mantiene
C20: =SUM(C4:C19) -> 212 | D20: =SUM(D4:D19) -> 47 | E20: =SUM(E4:E19) -> 51 | F20: =SUM(F4:F19) -> 53 | G20: =SUM(G4:G19) -> 20 | H20: =SUM(H4:H19) -> 25 | I20: =SUM(I4:I19) -> 408 | N20: Parcialmente funcional | T20: =COUNTIF('BD2'!AF:AF,Estadísticas!N20) -> 19 | V20: 89 | W20: =VLOOKUP(V20,'BD1'!$A$2:$AF$1139,31,0) -> 6 | X20: =VLOOKUP(V20,'BD2'!$A$2:$AF$1139,31,0) -> 8 | Y20: =IF(X20>W20,"Mejoría",IF(X20<W20,"Pérdida","Se mantiene")) -> Mejoría
N21: Inoperativo | T21: =COUNTIF('BD2'!AF:AF,Estadísticas!N21) -> 10 | V21: 92 | W21: =VLOOKUP(V21,'BD1'!$A$2:$AF$1139,31,0) -> 8 | X21: =VLOOKUP(V21,'BD2'!$A$2:$AF$1139,31,0) -> 8 | Y21: =IF(X21>W21,"Mejoría",IF(X21<W21,"Pérdida","Se mantiene")) -> Se mantiene
A22: Hay 9 sitios que no cuentan con video dando un total de 417 sitios con reporte | N22: Crítico | T22: =COUNTIF('BD2'!AF:AF,Estadísticas!N22) -> 24 | V22: 96 | W22: =VLOOKUP(V22,'BD1'!$A$2:$AF$1139,31,0) -> 8 | X22: =VLOOKUP(V22,'BD2'!$A$2:$AF$1139,31,0) -> 8 | Y22: =IF(X22>W22,"Mejoría",IF(X22<W22,"Pérdida","Se mantiene")) -> Se mantiene
V23: 101 | W23: =VLOOKUP(V23,'BD1'!$A$2:$AF$1139,31,0) -> 7 | X23: =VLOOKUP(V23,'BD2'!$A$2:$AF$1139,31,0) -> 8 | Y23: =IF(X23>W23,"Mejoría",IF(X23<W23,"Pérdida","Se mantiene")) -> Mejoría
A24: Comparación de error en la primer y segunda visita | V24: 102 | W24: =VLOOKUP(V24,'BD1'!$A$2:$AF$1139,31,0) -> 5 | X24: =VLOOKUP(V24,'BD2'!$A$2:$AF$1139,31,0) -> 7 | Y24: =IF(X24>W24,"Mejoría",IF(X24<W24,"Pérdida","Se mantiene")) -> Mejoría
V25: 107 | W25: =VLOOKUP(V25,'BD1'!$A$2:$AF$1139,31,0) -> 8 | X25: =VLOOKUP(V25,'BD2'!$A$2:$AF$1139,31,0) -> 8 | Y25: =IF(X25>W25,"Mejoría",IF(X25<W25,"Pérdida","Se mantiene")) -> Se mantiene
A26: CONEXIÓN FÁCIL | V26: 109 | W26: =VLOOKUP(V26,'BD1'!$A$2:$AF$1139,31,0) -> 8 | X26: =VLOOKUP(V26,'BD2'!$A$2:$AF$1139,31,0) -> 8 | Y26: =IF(X26>W26,"Mejoría",IF(X26<W26,"Pérdida","Se mantiene")) -> Se mantiene
A27: MUNICIPIO | B27: ERROR 1 | C27: ERROR 2 | D27: TOTAL | E27: % ERROR 1 | F27: % ÉXITO 1 | G27: % ERROR 2 | H27: % ÉXITO 2 | V27: 112 | W27: =VLOOKUP(V27,'BD1'!$A$2:$AF$1139,31,0) -> 7 | X27: =VLOOKUP(V27,'BD2'!$A$2:$AF$1139,31,0) -> 8 | Y27: =IF(X27>W27,"Mejoría",IF(X27<W27,"Pérdida","Se mantiene")) -> Mejoría
A28: León | B28: =COUNTIFS('BD1'!H:H,Estadísticas!A28,'BD1'!S:S,"no") -> 12 | C28: =COUNTIFS('BD2'!H:H,Estadísticas!A28,'BD2'!S:S,"no") -> 9 | D28: =(COUNTIFS('BD1'!H:H,Estadísticas!A28,'BD1'!K:K,"ok") + COUNTIFS('BD1'!H:H,Estadísticas!A28,'BD1'!K:K,"sin video")) -> 217 | E28: =B28*100/D28 -> 5.5299539 | F28: =(D28-B28)*100/D28 -> 94.470046 | G28: =C28*100/D28 -> 4.1474654 | H28: =(D28-C28)*100/D28 -> 95.852535 | V28: 114 | W28: =VLOOKUP(V28,'BD1'!$A$2:$AF$1139,31,0) -> 8 | X28: =VLOOKUP(V28,'BD2'!$A$2:$AF$1139,31,0) -> 0 | Y28: =IF(X28>W28,"Mejoría",IF(X28<W28,"Pérdida","Se mantiene")) -> Pérdida
A29: Silao | B29: =COUNTIFS('BD1'!H:H,Estadísticas!A29,'BD1'!S:S,"no") -> 5 | C29: =COUNTIFS('BD2'!H:H,Estadísticas!A29,'BD2'!S:S,"no") -> 0 | D29: =(COUNTIFS('BD1'!H:H,Estadísticas!A29,'BD1'!K:K,"ok") + COUNTIFS('BD1'!H:H,Estadísticas!A29,'BD1'!K:K,"sin video")) -> 47 | E29: =B29*100/D29 -> 10.638298 | F29: =(D29-B29)*100/D29 -> 89.361702 | G29: =C29*100/D29 -> 0 | H29: =(D29-C29)*100/D29 -> 100 | V29: 123 | W29: =VLOOKUP(V29,'BD1'!$A$2:$AF$1139,31,0) -> 8 | X29: =VLOOKUP(V29,'BD2'!$A$2:$AF$1139,31,0) -> 8 | Y29: =IF(X29>W29,"Mejoría",IF(X29<W29,"Pérdida","Se mantiene")) -> Se mantiene
A30: Guanajuato | B30: =COUNTIFS('BD1'!H:H,Estadísticas!A30,'BD1'!S:S,"no") -> 5 | C30: =COUNTIFS('BD2'!H:H,Estadísticas!A30,'BD2'!S:S,"no") -> 4 | D30: =(COUNTIFS('BD1'!H:H,Estadísticas!A30,'BD1'!K:K,"ok") + COUNTIFS('BD1'!H:H,Estadísticas!A30,'BD1'!K:K,"sin video")) -> 55 | E30: =B30*100/D30 -> 9.0909091 | F30: =(D30-B30)*100/D30 -> 90.909091 | G30: =C30*100/D30 -> 7.2727273 | H30: =(D30-C30)*100/D30 -> 92.727273 | V30: 128 | W30: =VLOOKUP(V30,'BD1'!$A$2:$AF$1139,31,0) -> 8 | X30: =VLOOKUP(V30,'BD2'!$A$2:$AF$1139,31,0) -> 8 | Y30: =IF(X30>W30,"Mejoría",IF(X30<W30,"Pérdida","Se mantiene")) -> Se mantiene
A31: Irapuato | B31: =COUNTIFS('BD1'!H:H,Estadísticas!A31,'BD1'!S:S,"no") -> 1 | C31: =COUNTIFS('BD2'!H:H,Estadísticas!A31,'BD2'!S:S,"no") -> 0 | D31: =(COUNTIFS('BD1'!H:H,Estadísticas!A31,'BD1'!K:K,"ok") + COUNTIFS('BD1'!H:H,Estadísticas!A31,'BD1'!K:K,"sin video")) -> 54 | E31: =B31*100/D31 -> 1.8518519 | F31: =(D31-B31)*100/D31 -> 98.148148 | G31: =C31*100/D31 -> 0 | H31: =(D31-C31)*100/D31 -> 100 | V31: 131 | W31: =VLOOKUP(V31,'BD1'!$A$2:$AF$1139,31,0) -> 8 | X31: =VLOOKUP(V31,'BD2'!$A$2:$AF$1139,31,0) -> 8 | Y31: =IF(X31>W31,"Mejoría",IF(X31<W31,"Pérdida","Se mantiene")) -> Se mantiene
A32: Salamanca | B32: =COUNTIFS('BD1'!H:H,Estadísticas!A32,'BD1'!S:S,"no") -> 3 | C32: =COUNTIFS('BD2'!H:H,Estadísticas!A32,'BD2'!S:S,"no") -> 3 | D32: =(COUNTIFS('BD1'!H:H,Estadísticas!A32,'BD1'!K:K,"ok") + COUNTIFS('BD1'!H:H,Estadísticas!A32,'BD1'!K:K,"sin video")) -> 20 | E32: =B32*100/D32 -> 15 | F32: =(D32-B32)*100/D32 -> 85 | G32: =C32*100/D32 -> 15 | H32: =(D32-C32)*100/D32 -> 85 | V32: 136 | W32: =VLOOKUP(V32,'BD1'!$A$2:$AF$1139,31,0) -> 8 | X32: =VLOOKUP(V32,'BD2'!$A$2:$AF$1139,31,0) -> 8 | Y32: =IF(X32>W32,"Mejoría",IF(X32<W32,"Pérdida","Se mantiene")) -> Se mantiene
A33: Celaya | B33: =COUNTIFS('BD1'!H:H,Estadísticas!A33,'BD1'!S:S,"no") -> 2 | C33: =COUNTIFS('BD2'!H:H,Estadísticas!A33,'BD2'!S:S,"no") -> 1 | D33: =(COUNTIFS('BD1'!H:H,Estadísticas!A33,'BD1'!K:K,"ok") + COUNTIFS('BD1'!H:H,Estadísticas!A33,'BD1'!K:K,"sin video")) -> 25 | E33: =B33*100/D33 -> 8 | F33: =(D33-B33)*100/D33 -> 92 | G33: =C33*100/D33 -> 4 | H33: =(D33-C33)*100/D33 -> 96 | V33: 141 | W33: =VLOOKUP(V33,'BD1'!$A$2:$AF$1139,31,0) -> 8 | X33: =VLOOKUP(V33,'BD2'!$A$2:$AF$1139,31,0) -> 8 | Y33: =IF(X33>W33,"Mejoría",IF(X33<W33,"Pérdida","Se mantiene")) -> Se mantiene
V34: 142 | W34: =VLOOKUP(V34,'BD1'!$A$2:$AF$1139,31,0) -> 8 | X34: =VLOOKUP(V34,'BD2'!$A$2:$AF$1139,31,0) -> 8 | Y34: =IF(X34>W34,"Mejoría",IF(X34<W34,"Pérdida","Se mantiene")) -> Se mantiene
A35: MENSAJERO | V35: 144 | W35: =VLOOKUP(V35,'BD1'!$A$2:$AF$1139,31,0) -> 8 | X35: =VLOOKUP(V35,'BD2'!$A$2:$AF$1139,31,0) -> 8 | Y35: =IF(X35>W35,"Mejoría",IF(X35<W35,"Pérdida","Se mantiene")) -> Se mantiene
A36: MUNICIPIO | B36: ERROR 1 | C36: ERROR 2 | D36: TOTAL | E36: % ERROR 1 | F36: % ÉXITO 1 | G36: % ERROR 2 | H36: % ÉXITO 2 | V36: 147 | W36: =VLOOKUP(V36,'BD1'!$A$2:$AF$1139,31,0) -> 8 | X36: =VLOOKUP(V36,'BD2'!$A$2:$AF$1139,31,0) -> 8 | Y36: =IF(X36>W36,"Mejoría",IF(X36<W36,"Pérdida","Se mantiene")) -> Se mantiene
A37: León | B37: =COUNTIFS('BD1'!H:H,Estadísticas!A37,'BD1'!T:T,"no") -> 9 | C37: =COUNTIFS('BD2'!H:H,Estadísticas!A37,'BD2'!T:T,"no") -> 17 | D37: =(COUNTIFS('BD1'!H:H,Estadísticas!A37,'BD1'!K:K,"ok") + COUNTIFS('BD1'!H:H,Estadísticas!A37,'BD1'!K:K,"sin video")) -> 217 | E37: =B37*100/D37 -> 4.1474654 | F37: =(D37-B37)*100/D37 -> 95.852535 | G37: =C37*100/D37 -> 7.8341014 | H37: =(D37-C37)*100/D37 -> 92.165899 | V37: 148 | W37: =VLOOKUP(V37,'BD1'!$A$2:$AF$1139,31,0) -> 8 | X37: =VLOOKUP(V37,'BD2'!$A$2:$AF$1139,31,0) -> 0 | Y37: =IF(X37>W37,"Mejoría",IF(X37<W37,"Pérdida","Se mantiene")) -> Pérdida
A38: Silao | B38: =COUNTIFS('BD1'!H:H,Estadísticas!A38,'BD1'!T:T,"no") -> 3 | C38: =COUNTIFS('BD2'!H:H,Estadísticas!A38,'BD2'!T:T,"no") -> 0 | D38: =(COUNTIFS('BD1'!H:H,Estadísticas!A38,'BD1'!K:K,"ok") + COUNTIFS('BD1'!H:H,Estadísticas!A38,'BD1'!K:K,"sin video")) -> 47 | E38: =B38*100/D38 -> 6.3829787 | F38: =(D38-B38)*100/D38 -> 93.617021 | G38: =C38*100/D38 -> 0 | H38: =(D38-C38)*100/D38 -> 100 | V38: 163 | W38: =VLOOKUP(V38,'BD1'!$A$2:$AF$1139,31,0) -> 8 | X38: =VLOOKUP(V38,'BD2'!$A$2:$AF$1139,31,0) -> 8 | Y38: =IF(X38>W38,"Mejoría",IF(X38<W38,"Pérdida","Se mantiene")) -> Se mantiene
A39: Guanajuato | B39: =COUNTIFS('BD1'!H:H,Estadísticas!A39,'BD1'!T:T,"no") -> 10 | C39: =COUNTIFS('BD2'!H:H,Estadísticas!A39,'BD2'!T:T,"no") -> 11 | D39: =(COUNTIFS('BD1'!H:H,Estadísticas!A39,'BD1'!K:K,"ok") + COUNTIFS('BD1'!H:H,Estadísticas!A39,'BD1'!K:K,"sin video")) -> 55 | E39: =B39*100/D39 -> 18.181818 | F39: =(D39-B39)*100/D39 -> 81.818182 | G39: =C39*100/D39 -> 20 | H39: =(D39-C39)*100/D39 -> 80 | V39: 164 | W39: =VLOOKUP(V39,'BD1'!$A$2:$AF$1139,31,0) -> 8 | X39: =VLOOKUP(V39,'BD2'!$A$2:$AF$1139,31,0) -> 8 | Y39: =IF(X39>W39,"Mejoría",IF(X39<W39,"Pérdida","Se mantiene")) -> Se mantiene
A40: Irapuato | B40: =COUNTIFS('BD1'!H:H,Estadísticas!A40,'BD1'!T:T,"no") -> 1 | C40: =COUNTIFS('BD2'!H:H,Estadísticas!A40,'BD2'!T:T,"no") -> 1 | D40: =(COUNTIFS('BD1'!H:H,Estadísticas!A40,'BD1'!K:K,"ok") + COUNTIFS('BD1'!H:H,Estadísticas!A40,'BD1'!K:K,"sin video")) -> 54 | E40: =B40*100/D40 -> 1.8518519 | F40: =(D40-B40)*100/D40 -> 98.148148 | G40: =C40*100/D40 -> 1.8518519 | H40: =(D40-C40)*100/D40 -> 98.148148 | V40: 200 | W40: =VLOOKUP(V40,'BD1'!$A$2:$AF$1139,31,0) -> 8 | X40: =VLOOKUP(V40,'BD2'!$A$2:$AF$1139,31,0) -> 8 | Y40: =IF(X40>W40,"Mejoría",IF(X40<W40,"Pérdida","Se mantiene")) -> Se mantiene
A41: Salamanca | B41: =COUNTIFS('BD1'!H:H,Estadísticas!A41,'BD1'!T:T,"no") -> 3 | C41: =COUNTIFS('BD2'!H:H,Estadísticas!A41,'BD2'!T:T,"no") -> 5 | D41: =(COUNTIFS('BD1'!H:H,Estadísticas!A41,'BD1'!K:K,"ok") + COUNTIFS('BD1'!H:H,Estadísticas!A41,'BD1'!K:K,"sin video")) -> 20 | E41: =B41*100/D41 -> 15 | F41: =(D41-B41)*100/D41 -> 85 | G41: =C41*100/D41 -> 25 | H41: =(D41-C41)*100/D41 -> 75 | V41: 202 | W41: =VLOOKUP(V41,'BD1'!$A$2:$AF$1139,31,0) -> 8 | X41: =VLOOKUP(V41,'BD2'!$A$2:$AF$1139,31,0) -> 7 | Y41: =IF(X41>W41,"Mejoría",IF(X41<W41,"Pérdida","Se mantiene")) -> Pérdida
...

Sheet BD1
A1: Sitio | B1: Tipo de conexión | C1: Tipo de espacio | D1: Tipo | E1: Nombre | F1: Ubicación | G1: Colonia | H1: Municipio | I1: Latitud | J1: Longitud | K1: Visitado | L1: Liga | M1: Aps | N1: Fecha de rev | O1: Día | P1: Mes | Q1: Año | R1: Visita | S1: Conexión fácil | T1: Mensajero | U1: Facebook | V1: Youtube | W1: Maps | X1: Navegador | Y1: Nav Constante | Z1: Buen ancho de banda | AA1: Bajada | AB1: Subida | AC1: Observaciones | AD1: Supervisor | AE1: Calificación | AF1: Situación
A2: 1 | B2: Fibra Óptica | C2: PLAZA PÚBLICA | D2: N/A | E2: CRUZ DE CANTERA (JUNTO A LAS CANCHAS DEL MALECON) | F2: CRUZ DE CANTERA SANTA FE | G2: COLONIA SANTA FE | H2: LEÓN | I2: 21.127368 | J2: -101.67531 | K2: ok | L2: =HYPERLINK("https://www.google.com/maps?q=" & I2 & "," & J2, "Ver en Google Maps") -> Ver en Google Maps | M2: 1 | N2: 45929 | O2: =DAY('BD1'!$N2) -> 29 | P2: =MONTH('BD1'!$N2) -> 9 | Q2: =YEAR('BD1'!$N2) -> 2025 | R2: 1 | S2: si | T2: si | U2: si | V2: si | W2: si | X2: si | Y2: si | Z2: si | AA2: 38.58 | AB2: 99.83 | AC2: La conexión fue rápida y constante, la navegación fue fluida, no se observan anomalías, tiene buena señal | AD2: José Mosqueda | AE2: =COUNTIF(S2:Z2, "si") -> 8 | AF2: =IF('BD1'!$AE2=8,"Estable",(IF('BD1'!$AE2=7,"Funcional con observaciones", (IF('BD1'!$AE2=6,"Funcional con observaciones",(IF('BD1'!$AE2=5,"Rendimiento bajo",(IF('BD1'!$AE2=4,"Parcialmente funcional",(IF('BD1'!$AE2=3,"Parcialmente funcional",(IF('BD1'!$AE2=2,"Inoperativo",(IF('BD1'!$AE2=1,"Inoperativo","Crítico"))))))))))))))) -> Estable
A3: 2 | B3: Fibra Óptica | C3: PLAZA PÚBLICA | D3: N/A | E3: JARDINES DE SAN SEBASTIAN | F3: JARDINES DE SAN SEBASTIAN II | G3: COLONIA SAN SEBASTIAN | H3: LEÓN | I3: 21.099483 | J3: -101.6999 | K3: ok | L3: =HYPERLINK("https://www.google.com/maps?q=" & I3 & "," & J3, "Ver en Google Maps") -> Ver en Google Maps | M3: 1 | N3: 45932 | O3: =DAY('BD1'!$N3) -> 2 | P3: =MONTH('BD1'!$N3) -> 10 | Q3: =YEAR('BD1'!$N3) -> 2025 | R3: 1 | S3: si | T3: si | U3: si | V3: si | W3: si | X3: si | Y3: si | Z3: si | AA3: 15.85 | AB3: 11.85 | AC3: La conexión fue rápida y constante, la navegación fue fluida, no se observan anomalías, tiene buena señal | AD3: José Mosqueda | AE3: =COUNTIF(S3:Z3, "si") -> 8 | AF3: =IF('BD1'!$AE3=8,"Estable",(IF('BD1'!$AE3=7,"Funcional con observaciones", (IF('BD1'!$AE3=6,"Funcional con observaciones",(IF('BD1'!$AE3=5,"Rendimiento bajo",(IF('BD1'!$AE3=4,"Parcialmente funcional",(IF('BD1'!$AE3=3,"Parcialmente funcional",(IF('BD1'!$AE3=2,"Inoperativo",(IF('BD1'!$AE3=1,"Inoperativo","Crítico"))))))))))))))) -> Estable
A4: 3 | B4: Fibra Óptica | C4: PLAZA PÚBLICA | D4: N/A | E4: PLAZA COMUNITARIA VILLA DE LAS FLORES | F4: HEROES DE LA INDEPENDENCIA VILLA DE LAS FLORES | G4: COLONIA VILLA DE LAS FLORES | H4: LEÓN | I4: 21.122248 | J4: -101.6506 | K4: ok | L4: =HYPERLINK("https://www.google.com/maps?q=" & I4 & "," & J4, "Ver en Google Maps") -> Ver en Google Maps | M4: 1 | N4: 45931 | O4: =DAY('BD1'!$N4) -> 1 | P4: =MONTH('BD1'!$N4) -> 10 | Q4: =YEAR('BD1'!$N4) -> 2025 | R4: 1 | S4: si | T4: si | U4: si | V4: si | W4: si | X4: si | Y4: si | Z4: si | AA4: 22.41 | AB4: 29.07 | AC4: La conexión fue rápida y constante, la navegación fue fluida, no se observan anomalías, tiene buena señal | AD4: José Mosqueda | AE4: =COUNTIF(S4:Z4, "si") -> 8 | AF4: =IF('BD1'!$AE4=8,"Estable",(IF('BD1'!$AE4=7,"Funcional con observaciones", (IF('BD1'!$AE4=6,"Funcional con observaciones",(IF('BD1'!$AE4=5,"Rendimiento bajo",(IF('BD1'!$AE4=4,"Parcialmente funcional",(IF('BD1'!$AE4=3,"Parcialmente funcional",(IF('BD1'!$AE4=2,"Inoperativo",(IF('BD1'!$AE4=1,"Inoperativo","Crítico"))))))))))))))) -> Estable
A5: 4 | B5: Fibra Óptica | C5: PLAZA PÚBLICA | D5: N/A | E5: PLAZA PUBLICA EL LUCERO | F5: MARFIX EL LUCERO II | G5: COLONIA EL LUCERO | H5: LEÓN | I5: 21.136565 | J5: -101.66825 | K5: ok | L5: =HYPERLINK("https://www.google.com/maps?q=" & I5 & "," & J5, "Ver en Google Maps") -> Ver en Google Maps | M5: 1 | N5: 45930 | O5: =DAY('BD1'!$N5) -> 30 | P5: =MONTH('BD1'!$N5) -> 9 | Q5: =YEAR('BD1'!$N5) -> 2025 | R5: 1 | S5: si | T5: si | U5: si | V5: si | W5: si | X5: si | Y5: si | Z5: si | AA5: 16.96 | AB5: 20.38 | AC5: La conexión fue rápida y constante, la navegación fue fluida, no se observan anomalías, tiene buena señal | AD5: José Mosqueda | AE5: =COUNTIF(S5:Z5, "si") -> 8 | AF5: =IF('BD1'!$AE5=8,"Estable",(IF('BD1'!$AE5=7,"Funcional con observaciones", (IF('BD1'!$AE5=6,"Funcional con observaciones",(IF('BD1'!$AE5=5,"Rendimiento bajo",(IF('BD1'!$AE5=4,"Parcialmente funcional",(IF('BD1'!$AE5=3,"Parcialmente funcional",(IF('BD1'!$AE5=2,"Inoperativo",(IF('BD1'!$AE5=1,"Inoperativo","Crítico"))))))))))))))) -> Estable
A6: 5 | B6: Fibra Óptica | C6: ESPACIO DEPORTIVO | D6: N/A | E6: AGUA AZUL | F6: DELTA AGUA AZUL | G6: COLONIA AGUA AZUL | H6: LEÓN | I6: 21.103264 | J6: -101.61151 | K6: ok | L6: =HYPERLINK("https://www.google.com/maps?q=" & I6 & "," & J6, "Ver en Google Maps") -> Ver en Google Maps | M6: 1 | N6: 45931 | O6: =DAY('BD1'!$N6) -> 1 | P6: =MONTH('BD1'!$N6) -> 10 | Q6: =YEAR('BD1'!$N6) -> 2025 | R6: 1 | S6: si | T6: si | U6: si | V6: si | W6: si | X6: si | Y6: si | Z6: si | AA6: 24.05 | AB6: 33.33 | AC6: La conexión fue rápida y constante, la navegación fue fluida, no se observan anomalías, tiene buena señal | AD6: José Mosqueda | AE6: =COUNTIF(S6:Z6, "si") -> 8 | AF6: =IF('BD1'!$AE6=8,"Estable",(IF('BD1'!$AE6=7,"Funcional con observaciones", (IF('BD1'!$AE6=6,"Funcional con observaciones",(IF('BD1'!$AE6=5,"Rendimiento bajo",(IF('BD1'!$AE6=4,"Parcialmente funcional",(IF('BD1'!$AE6=3,"Parcialmente funcional",(IF('BD1'!$AE6=2,"Inoperativo",(IF('BD1'!$AE6=1,"Inoperativo","Crítico"))))))))))))))) -> Estable
A7: 6 | B7: Fibra Óptica | C7: ESPACIO DEPORTIVO | D7: N/A | E7: LOS ANGELES | F7: VALLE DE LOS NOGALES ANGELES, LOS | G7: COLONIA LOS ANGELES | H7: LEÓN | I7: 21.131813 | J7: -101.64046 | K7: ok | L7: =HYPERLINK("https://www.google.com/maps?q=" & I7 & "," & J7, "Ver en Google Maps") -> Ver en Google Maps | M7: 1 | N7: 45929 | O7: =DAY('BD1'!$N7) -> 29 | P7: =MONTH('BD1'!$N7) -> 9 | Q7: =YEAR('BD1'!$N7) -> 2025 | R7: 1 | S7: si | T7: si | U7: si | V7: si | W7: si | X7: si | Y7: si | Z7: si | AA7: 44.23 | AB7: 12.18 | AC7: La conexión fue rápida y constante, la navegación fue fluida, no se observan anomalías, tiene buena señal | AD7: José Mosqueda | AE7: =COUNTIF(S7:Z7, "si") -> 8 | AF7: =IF('BD1'!$AE7=8,"Estable",(IF('BD1'!$AE7=7,"Funcional con observaciones", (IF('BD1'!$AE7=6,"Funcional con observaciones",(IF('BD1'!$AE7=5,"Rendimiento bajo",(IF('BD1'!$AE7=4,"Parcialmente funcional",(IF('BD1'!$AE7=3,"Parcialmente funcional",(IF('BD1'!$AE7=2,"Inoperativo",(IF('BD1'!$AE7=1,"Inoperativo","Crítico"))))))))))))))) -> Estable
A8: 7 | B8: Fibra Óptica | C8: ESPACIO DEPORTIVO | D8: N/A | E8: CENTRO DEPORTIVO LAS JOYAS | F8: BALCÓN DE LOS RUISEÑORES 208, BALCONES DE LA JOYA, 37355 LEÓN, GTO. | G8: COLONIA BALCONES DE LA JOYA | H8: LEÓN | I8: 21.12784 | J8: -101.74435 | K8: ok | L8: =HYPERLINK("https://www.google.com/maps?q=" & I8 & "," & J8, "Ver en Google Maps") -> Ver en Google Maps | M8: 1 | N8: 45930 | O8: =DAY('BD1'!$N8) -> 30 | P8: =MONTH('BD1'!$N8) -> 9 | Q8: =YEAR('BD1'!$N8) -> 2025 | R8: 1 | S8: si | T8: si | U8: si | V8: si | W8: si | X8: si | Y8: si | Z8: si | AA8: 24.94 | AB8: 11.13 | AC8: La conexión fue rápida y constante, la navegación fue fluida, no se observan anomalías, tiene buena señal | AD8: José Mosqueda | AE8: =COUNTIF(S8:Z8, "si") -> 8 | AF8: =IF('BD1'!$AE8=8,"Estable",(IF('BD1'!$AE8=7,"Funcional con observaciones", (IF('BD1'!$AE8=6,"Funcional con observaciones",(IF('BD1'!$AE8=5,"Rendimiento bajo",(IF('BD1'!$AE8=4,"Parcialmente funcional",(IF('BD1'!$AE8=3,"Parcialmente funcional",(IF('BD1'!$AE8=2,"Inoperativo",(IF('BD1'!$AE8=1,"Inoperativo","Crítico"))))))))))))))) -> Estable
A9: 8 | B9: Fibra Óptica | C9: ESPACIO DEPORTIVO | D9: N/A | E9: DEPORTIVA I (UNIDAD DEPORTIVA I) | F9: TABLERO DEPORTIVA I | G9: COLONIA LEÓN I | H9: LEÓN | I9: 21.145551 | J9: -101.65661 | K9: ok | L9: =HYPERLINK("https://www.google.com/maps?q=" & I9 & "," & J9, "Ver en Google Maps") -> Ver en Google Maps | M9: 1 | N9: 45929 | O9: =DAY('BD1'!$N9) -> 29 | P9: =MONTH('BD1'!$N9) -> 9 | Q9: =YEAR('BD1'!$N9) -> 2025 | R9: 1 | S9: si | T9: si | U9: si | V9: si | W9: si | X9: si | Y9: si | Z9: si | AA9: 82.91 | AB9: 82.39 | AC9: La conexión fue rápida y constante, la navegación fue fluida, no se observan anomalías, tiene buena señal | AD9: José Mosqueda | AE9: =COUNTIF(S9:Z9, "si") -> 8 | AF9: =IF('BD1'!$AE9=8,"Estable",(IF('BD1'!$AE9=7,"Funcional con observaciones", (IF('BD1'!$AE9=6,"Funcional con observaciones",(IF('BD1'!$AE9=5,"Rendimiento bajo",(IF('BD1'!$AE9=4,"Parcialmente funcional",(IF('BD1'!$AE9=3,"Parcialmente funcional",(IF('BD1'!$AE9=2,"Inoperativo",(IF('BD1'!$AE9=1,"Inoperativo","Crítico"))))))))))))))) -> Estable
A10: 9 | B10: Fibra Óptica | C10: ESPACIO DEPORTIVO | D10: N/A | E10: ECHEVESTE 2000 | F10: NABO ECHEVESTE 2000 | G10: COLONIA ECHEVESTE 2000 | H10: LEÓN | I10: 21.179691 | J10: -101.67001 | K10: ok | L10: =HYPERLINK("https://www.google.com/maps?q=" & I10 & "," & J10, "Ver en Google Maps") -> Ver en Google Maps | M10: 1 | N10: 45929 | O10: =DAY('BD1'!$N10) -> 29 | P10: =MONTH('BD1'!$N10) -> 9 | Q10: =YEAR('BD1'!$N10) -> 2025 | R10: 1 | S10: si | T10: si | U10: si | V10: si | W10: si | X10: si | Y10: si | Z10: no | AA10: 10.92 | AB10: 11.86 | AC10: La conexión fue rápida y constante, la navegación fue fluida, no se observan anomalías, tiene buena señal, el ancho de banda es bajo sobre todo en la descarga | AD10: José Mosqueda | AE10: =COUNTIF(S10:Z10, "si") -> 7 | AF10: =IF('BD1'!$AE10=8,"Estable",(IF('BD1'!$AE10=7,"Funcional con observaciones", (IF('BD1'!$AE10=6,"Funcional con observaciones",(IF('BD1'!$AE10=5,"Rendimiento bajo",(IF('BD1'!$AE10=4,"Parcialmente funcional",(IF('BD1'!$AE10=3,"Parcialmente funcional",(IF('BD1'!$AE10=2,"Inoperativo",(IF('BD1'!$AE10=1,"Inoperativo","Crítico"))))))))))))))) -> Funcional con observaciones
A11: 10 | B11: Fibra Óptica | C11: ESPACIO DEPORTIVO | D11: N/A | E11: ECHEVESTE | F11: HERMENEGILDO BUSTOS HACIENDA ECHEVESTE | G11: COLONIA HACIENDA ECHEVESTE | H11: LEÓN | I11: 21.187876 | J11: -101.66685 | K11: ok | L11: =HYPERLINK("https://www.google.com/maps?q=" & I11 & "," & J11, "Ver en Google Maps") -> Ver en Google Maps | M11: 1 | N11: 45929 | O11: =DAY('BD1'!$N11) -> 29 | P11: =MONTH('BD1'!$N11) -> 9 | Q11: =YEAR('BD1'!$N11) -> 2025 | R11: 1 | S11: si | T11: si | U11: si | V11: si | W11: si | X11: si | Y11: si | Z11: si | AA11: 41.69 | AB11: 29.36 | AC11: La conexión fue rápida y constante, la navegación fue fluida, no se observan anomalías, tiene buena señal | AD11: José Mosqueda | AE11: =COUNTIF(S11:Z11, "si") -> 8 | AF11: =IF('BD1'!$AE11=8,"Estable",(IF('BD1'!$AE11=7,"Funcional con observaciones", (IF('BD1'!$AE11=6,"Funcional con observaciones",(IF('BD1'!$AE11=5,"Rendimiento bajo",(IF('BD1'!$AE11=4,"Parcialmente funcional",(IF('BD1'!$AE11=3,"Parcialmente funcional",(IF('BD1'!$AE11=2,"Inoperativo",(IF('BD1'!$AE11=1,"Inoperativo","Crítico"))))))))))))))) -> Estable
A12: 11 | B12: Fibra Óptica | C12: ESPACIO DEPORTIVO | D12: N/A | E12: PARQUE IV CENTENARIO | F12: MONTE DE LAS CRUCES HIDALGO | G12: COLONIA HIDALGO | H12: LEÓN | I12: 21.143558 | J12: -101.66958 | K12: ok | L12: =HYPERLINK("https://www.google.com/maps?q=" & I12 & "," & J12, "Ver en Google Maps") -> Ver en Google Maps | M12: 1 | N12: 45929 | O12: =DAY('BD1'!$N12) -> 29 | P12: =MONTH('BD1'!$N12) -> 9 | Q12: =YEAR('BD1'!$N12) -> 2025 | R12: 1 | S12: si | T12: si | U12: si | V12: si | W12: si | X12: si | Y12: si | Z12: si | AA12: 51.76 | AB12: 54.04 | AC12: La conexión fue rápida y constante, la navegación fue fluida, no se observan anomalías, tiene buena señal | AD12: José Mosqueda | AE12: =COUNTIF(S12:Z12, "si") -> 8 | AF12: =IF('BD1'!$AE12=8,"Estable",(IF('BD1'!$AE12=7,"Funcional con observaciones", (IF('BD1'!$AE12=6,"Funcional con observaciones",(IF('BD1'!$AE12=5,"Rendimiento bajo",(IF('BD1'!$AE12=4,"Parcialmente funcional",(IF('BD1'!$AE12=3,"Parcialmente funcional",(IF('BD1'!$AE12=2,"Inoperativo",(IF('BD1'!$AE12=1,"Inoperativo","Crítico"))))))))))))))) -> Estable
A13: 12 | B13: Fibra Óptica | C13: ESPACIO DEPORTIVO | D13: N/A | E13: PARQUE EXTREMO LAS HILAMAS | F13: MARIANO ESCOBEDO LOMAS DE LAS HILAMAS | G13: COLONIA LOMAS DE LAS HILAMAS | H13: LEÓN | I13: 21.110986 | J13: -101.72374 | K13: ok | L13: =HYPERLINK("https://www.google.com/maps?q=" & I13 & "," & J13, "Ver en Google Maps") -> Ver en Google Maps | M13: 2 | N13: 45933 | O13: =DAY('BD1'!$N13) -> 3 | P13: =MONTH('BD1'!$N13) -> 10 | Q13: =YEAR('BD1'!$N13) -> 2025 | R13: 1 | S13: si | T13: si | U13: si | V13: si | W13: si | X13: si | Y13: si | Z13: si | AA13: 26.73 | AB13: 46.48 | AC13: La conexión fue rápida y constante, la navegación fue fluida, no se observan anomalías, tiene buena señal | AD13: José Mosqueda | AE13: =COUNTIF(S13:Z13, "si") -> 8 | AF13: =IF('BD1'!$AE13=8,"Estable",(IF('BD1'!$AE13=7,"Funcional con observaciones", (IF('BD1'!$AE13=6,"Funcional con observaciones",(IF('BD1'!$AE13=5,"Rendimiento bajo",(IF('BD1'!$AE13=4,"Parcialmente funcional",(IF('BD1'!$AE13=3,"Parcialmente funcional",(IF('BD1'!$AE13=2,"Inoperativo",(IF('BD1'!$AE13=1,"Inoperativo","Crítico"))))))))))))))) -> Estable
A14: 13a | B14: Fibra Óptica | C14: ESPACIO DEPORTIVO | D14: N/A | E14: PARQUE DEL ARBOL | F14: TORRES LANDA, JUAN JOSE SAN NICOLAS | G14: COLONIA SAN NICOLAS | H14: LEÓN | I14: 21.102383 | J14: -101.67667 | K14: ok | L14: =HYPERLINK("https://www.google.com/maps?q=" & I14 & "," & J14, "Ver en Google Maps") -> Ver en Google Maps | M14: 3 | N14: 45932 | O14: =DAY('BD1'!$N14) -> 2 | P14: =MONTH('BD1'!$N14) -> 10 | Q14: =YEAR('BD1'!$N14) -> 2025 | R14: 1 | S14: si | T14: si | U14: si | V14: si | W14: si | X14: si | Y14: si | Z14: si | AA14: 19.33 | AB14: 4.61 | AC14: La conexión fue rápida y constante, la navegación fue fluida, no se observan anomalías, tiene buena señal | AD14: José Mosqueda | AE14: =COUNTIF(S14:Z14, "si") -> 8 | AF14: =IF('BD1'!$AE14=8,"Estable",(IF('BD1'!$AE14=7,"Funcional con observaciones", (IF('BD1'!$AE14=6,"Funcional con observaciones",(IF('BD1'!$AE14=5,"Rendimiento bajo",(IF('BD1'!$AE14=4,"Parcialmente funcional",(IF('BD1'!$AE14=3,"Parcialmente funcional",(IF('BD1'!$AE14=2,"Inoperativo",(IF('BD1'!$AE14=1,"Inoperativo","Crítico"))))))))))))))) -> Estable
A15: 13b | B15: Fibra Óptica | C15: ESPACIO DEPORTIVO | D15: N/A | E15: PARQUE DEL ARBOL | F15: TORRES LANDA, JUAN JOSE SAN NICOLAS | G15: COLONIA SAN NICOLAS | H15: LEÓN | I15: 21.103049 | J15: -101.67521 | K15: ok | L15: =HYPERLINK("https://www.google.com/maps?q=" & I15 & "," & J15, "Ver en Google Maps") -> Ver en Google Maps | M15: 3 | N15: 45932 | O15: =DAY('BD1'!$N15) -> 2 | P15: =MONTH('BD1'!$N15) -> 10 | Q15: =YEAR('BD1'!$N15) -> 2025 | R15: 1 | S15: si | T15: si | U15: si | V15: si | W15: si | X15: si | Y15: si | Z15: no | AA15: 13.7 | AB15: 13.82 | AC15: La conexión fue rápida y constante, la navegación fue fluida, no se observan anomalías, tiene buena señal aunque un poco bajo el ancho de banda | AD15: José Mosqueda | AE15: =COUNTIF(S15:Z15, "si") -> 7 | AF15: =IF('BD1'!$AE15=8,"Estable",(IF('BD1'!$AE15=7,"Funcional con observaciones", (IF('BD1'!$AE15=6,"Funcional con observaciones",(IF('BD1'!$AE15=5,"Rendimiento bajo",(IF('BD1'!$AE15=4,"Parcialmente funcional",(IF('BD1'!$AE15=3,"Parcialmente funcional",(IF('BD1'!$AE15=2,"Inoperativo",(IF('BD1'!$AE15=1,"Inoperativo","Crítico"))))))))))))))) -> Funcional con observaciones
A16: 14 | B16: Fibra Óptica | C16: ESPACIO DEPORTIVO | D16: N/A | E16: MINIDEPORTIVA LOMA DORADA | F16: BLVD. MINERAL DE LA JOYA TORRES DORADAS | G16: COLONIA LOMA DORADA | H16: LEÓN | I16: 21.137276 | J16: -101.76616 | K16: ok | L16: =HYPERLINK("https://www.google.com/maps?q=" & I16 & "," & J16, "Ver en Google Maps") -> Ver en Google Maps | M16: 1 | N16: 45930 | O16: =DAY('BD1'!$N16) -> 30 | P16: =MONTH('BD1'!$N16) -> 9 | Q16: =YEAR('BD1'!$N16) -> 2025 | R16: 1 | S16: si | T16: si | U16: si | V16: si | W16: si | X16: si | Y16: si | Z16: si | AA16: 24.28 | AB16: 8.78 | AC16: La conexión fue rápida y constante, la navegación fue fluida, no se observan anomalías, tiene buena señal | AD16: José Mosqueda | AE16: =COUNTIF(S16:Z16, "si") -> 8 | AF16: =IF('BD1'!$AE16=8,"Estable",(IF('BD1'!$AE16=7,"Funcional con observaciones", (IF('BD1'!$AE16=6,"Funcional con observaciones",(IF('BD1'!$AE16=5,"Rendimiento bajo",(IF('BD1'!$AE16=4,"Parcialmente funcional",(IF('BD1'!$AE16=3,"Parcialmente funcional",(IF('BD1'!$AE16=2,"Inoperativo",(IF('BD1'!$AE16=1,"Inoperativo","Crítico"))))))))))))))) -> Estable
A17: 15 | B17: Fibra Óptica | C17: ESPACIO DEPORTIVO | D17: N/A | E17: VALLE DE SEÑORA I | F17: AVOGADRO VALLE DE SEÑORA | G17: COLONIA VALLE DE SEÑORA | H17: LEÓN | I17: 21.15992 | J17: -101.65658 | K17: ok | L17: =HYPERLINK("https://www.google.com/maps?q=" & I17 & "," & J17, "Ver en Google Maps") -> Ver en Google Maps | M17: 1 | N17: 45931 | O17: =DAY('BD1'!$N17) -> 1 | P17: =MONTH('BD1'!$N17) -> 10 | Q17: =YEAR('BD1'!$N17) -> 2025 | R17: 1 | S17: si | T17: si | U17: si | V17: si | W17: si | X17: si | Y17: si | Z17: si | AA17: 42.29 | AB17: 25.19 | AC17: La conexión fue rápida y constante, la navegación fue fluida, no se observan anomalías, tiene buena señal | AD17: José Mosqueda | AE17: =COUNTIF(S17:Z17, "si") -> 8 | AF17: =IF('BD1'!$AE17=8,"Estable",(IF('BD1'!$AE17=7,"Funcional con observaciones", (IF('BD1'!$AE17=6,"Funcional con observaciones",(IF('BD1'!$AE17=5,"Rendimiento bajo",(IF('BD1'!$AE17=4,"Parcialmente funcional",(IF('BD1'!$AE17=3,"Parcialmente funcional",(IF('BD1'!$AE17=2,"Inoperativo",(IF('BD1'!$AE17=1,"Inoperativo","Crítico"))))))))))))))) -> Estable
A18: 16 | B18: Fibra Óptica | C18: PRESIDENCIA | D18: N/A | E18: PRESIDENCIA MUNICIPAL DE LEÓN DE LOS ALDAMA | F18: PLAZA PRINCIPAL | G18: COLONIA CENTRO | H18: LEÓN | I18: 21.12176 | J18: -101.68234 | K18: ok | L18: =HYPERLINK("https://www.google.com/maps?q=" & I18 & "," & J18, "Ver en Google Maps") -> Ver en Google Maps | M18: 3 | N18: 45929 | O18: =DAY('BD1'!$N18) -> 29 | P18: =MONTH('BD1'!$N18) -> 9 | Q18: =YEAR('BD1'!$N18) -> 2025 | R18: 1 | S18: si | T18: si | U18: si | V18: si | W18: si | X18: si | Y18: si | Z18: si | AA18: 32.22 | AB18: 42.12 | AC18: La conexión fue rápida y constante, la navegación fue fluida, no se observan anomalías, tiene buena señal | AD18: José Mosqueda | AE18: =COUNTIF(S18:Z18, "si") -> 8 | AF18: =IF('BD1'!$AE18=8,"Estable",(IF('BD1'!$AE18=7,"Funcional con observaciones", (IF('BD1'!$AE18=6,"Funcional con observaciones",(IF('BD1'!$AE18=5,"Rendimiento bajo",(IF('BD1'!$AE18=4,"Parcialmente funcional",(IF('BD1'!$AE18=3,"Parcialmente funcional",(IF('BD1'!$AE18=2,"Inoperativo",(IF('BD1'!$AE18=1,"Inoperativo","Crítico"))))))))))))))) -> Estable
A19: 88 | B19: Fibra Óptica | C19: CENTRO DE INVESTIGACIÓN | D19: N/A | E19: HUB-I CASA DEL EMPRENDEDOR LEÓN | F19: CALLE JULIÁN DE OBREGÓN 245, OBREGÓN, 37320 LEÓN DE LOS ALDAMA, GTO. | G19: COLONIA LA MARTINICA | H19: LEÓN | I19: 21.129923 | J19: -101.68584 | L19: =HYPERLINK("https://www.google.com/maps?q=" & I19 & "," & J19, "Ver en Google Maps") -> Ver en Google Maps | M19: 2
A20: 89 | B20: Fibra Óptica | C20: ESCUELA | D20: SECUNDARIA | E20: 11EPR0645S -SECUNDARIA ANEXA NORMAL OFICIAL | F20: MERCURIO S/N, EL LUCERO, 37249, LEON DE LOS ALDAMA | G20: COLONIA EL LUCERO | H20: LEÓN | I20: 21.13566 | J20: -101.66829 | K20: ok | L20: =HYPERLINK("https://www.google.com/maps?q=" & I20 & "," & J20, "Ver en Google Maps") -> Ver en Google Maps | M20: 1 | N20: 45929 | O20: =DAY('BD1'!$N20) -> 29 | P20: =MONTH('BD1'!$N20) -> 9 | Q20: =YEAR('BD1'!$N20) -> 2025 | R20: 1 | S20: si | T20: si | U20: si | V20: si | W20: si | X20: si | Y20: no | Z20: no | AA20: 8.78 | AB20: 37 | AC20: La conexión es intermitente y tiene pocos megas de bajada, puede deberse a que el acces point está lejos de la calle y no se nos permitió el ingreso al plantel | AD20: José Mosqueda | AE20: =COUNTIF(S20:Z20, "si") -> 6 | AF20: =IF('BD1'!$AE20=8,"Estable",(IF('BD1'!$AE20=7,"Funcional con observaciones", (IF('BD1'!$AE20=6,"Funcional con observaciones",(IF('BD1'!$AE20=5,"Rendimiento bajo",(IF('BD1'!$AE20=4,"Parcialmente funcional",(IF('BD1'!$AE20=3,"Parcialmente funcional",(IF('BD1'!$AE20=2,"Inoperativo",(IF('BD1'!$AE20=1,"Inoperativo","Crítico"))))))))))))))) -> Funcional con observaciones
A21: 92 | B21: Fibra Óptica | C21: ESCUELA | D21: PREESCOLAR | E21: 11DJN4405E - OVIDIO DECROLY | F21: CALLE CHIMALPOPOCA NUMERO EXTERIOR: 102 , COLONIA AZTECAS, CODIGO | G21: COLONIA AZTECAS | H21: LEÓN | I21: 21.10199 | J21: -101.65482 | K21: ok | L21: =HYPERLINK("https://www.google.com/maps?q=" & I21 & "," & J21, "Ver en Google Maps") -> Ver en Google Maps | M21: 1 | N21: 45934 | O21: =DAY('BD1'!$N21) -> 4 | P21: =MONTH('BD1'!$N21) -> 10 | Q21: =YEAR('BD1'!$N21) -> 2025 | R21: 1 | S21: si | T21: si | U21: si | V21: si | W21: si | X21: si | Y21: si | Z21: si | AA21: 21.54 | AB21: 10.94 | AC21: La conexión fue rápida y constante, la navegación fue fluida, no se observan anomalías, tiene buena señal | AD21: José Mosqueda | AE21: =COUNTIF(S21:Z21, "si") -> 8 | AF21: =IF('BD1'!$AE21=8,"Estable",(IF('BD1'!$AE21=7,"Funcional con observaciones", (IF('BD1'!$AE21=6,"Funcional con observaciones",(IF('BD1'!$AE21=5,"Rendimiento bajo",(IF('BD1'!$AE21=4,"Parcialmente funcional",(IF('BD1'!$AE21=3,"Parcialmente funcional",(IF('BD1'!$AE21=2,"Inoperativo",(IF('BD1'!$AE21=1,"Inoperativo","Crítico"))))))))))))))) -> Estable
